Workbook

Sheet Instrucciones
A1: VeriTech · Cómo usar este libro de resultados
A3: Este libro calcula solo los resultados de la prueba. Tú únicamente pegas los datos; no hace falta escribir fórmulas ni tocar las demás hojas.
A5: Paso 1 · Descargar los 3 archivos de Netlify
A6: 1 | B6: Entra a Netlify, abre el sitio de VeriTech y ve a Forms (Formularios).
A7: 2 | B7: Haz clic en el formulario «calibracion» y luego en el botón Download CSV. Se descarga un archivo .csv.
A8: 3 | B8: Repite con «opinion-docentes» y con «opinion-sobre-la-web» (este es el de los estudiantes).
A10: Paso 2 · Abrir cada CSV respetando las tildes (UTF-8)
A11: 1 | B11: En Excel, crea un libro NUEVO y en blanco (Archivo → Nuevo). No lo hagas dentro de este libro.
A12: 2 | B12: En ese libro nuevo ve a la pestaña Datos → Desde texto/CSV y elige el archivo descargado.
A13: 3 | B13: En «Origen del archivo» elige «65001: Unicode (UTF-8)». Revisa que palabras como «Comunicación» se vean bien, con su tilde. Luego pulsa Cargar.
A14: · | B14: En Mac, si no ves «Desde texto/CSV», usa Archivo → Importar → Archivo CSV y elige «Unicode (UTF-8)» como origen del archivo.
A16: Paso 3 · Pegar los datos aquí
A17: 1 | B17: En el libro nuevo, haz clic en cualquier celda de la tabla y pulsa Ctrl+A (en Mac, Cmd+A) dos veces para seleccionar todo, incluida la fila de títulos. Copia con Ctrl+C (Cmd+C).
A18: 2 | B18: Vuelve a este libro y abre la hoja que corresponde: • calibracion → hoja «Pegar calibracion» • opinion-docentes → hoja «Pegar docentes» • opinion-sobre-la-web → hoja «Pegar estudiantes»
A19: 3 | B19: Haz clic en la celda A1 (arriba a la izquierda) y pega con Ctrl+V (Cmd+V). La fila 1 tiene que ser la de los títulos (docente, area, url…).
A20: 4 | B20: Abre la hoja «Resumen»: todos los números y gráficos ya están actualizados.
A22: Para actualizar con datos nuevos
A23: 1 | B23: Descarga el CSV otra vez: Netlify siempre entrega todas las respuestas, no solo las nuevas.
A24: 2 | B24: En la hoja «Pegar …», haz clic en el cuadrito de la esquina (arriba a la izquierda, sobre la fila 1) y pulsa Suprimir para borrar lo anterior. Después pega en A1 como en el paso 3.
A26: Qué hay en cada hoja
A27: · | B27: Resumen: los 4 criterios para pedir el piloto (✓ se cumple, ✕ no se cumple, «sin datos» falta el CSV), la calibración, la opinión de docentes y de estudiantes, con gráficos.
A28: · | B28: Pegar calibracion / Pegar docentes / Pegar estudiantes: el único lugar donde se pega. Las columnas pueden venir en cualquier orden y con columnas de más: el libro las busca por su nombre.
A29: · | B29: Calibracion / Docentes / Estudiantes: los datos ordenados y las columnas calculadas (en gris). La fila 2 dice en qué columna encontró cada dato o «no está en el CSV». Se llenan solas: no se escriben.
A31: Si algo no se ve bien
A32: · | B32: Letras raras en lugar de tildes (por ejemplo «ComunicaciÃ³n»): repite el paso 2 eligiendo UTF-8.
A33: · | B33: Todo sale «sin datos»: revisa que pegaste en A1 de la hoja correcta y que la fila 1 tiene los títulos.
A34: · | B34: Una columna dice «no está en el CSV»: descargaste otro formulario o la columna cambió de nombre en la web.
A35: · | B35: Las hojas que no son «Pegar …» están protegidas para no borrar fórmulas por error (Revisar → Desproteger hoja, sin contraseña).

Sheet Resumen
A1: VeriTech · Resultados de la prueba del colegio
A2: Esta hoja se calcula sola con lo que pegues en las hojas «Pegar …». No escribas aquí.
A4: ¿Pedimos el piloto? Los 4 criterios
A5: Criterio | B5: Valor | C5: Meta | D5: ¿Se cumple? | E5: Detalle
A6: 1. El semáforo coincide con los docentes en al menos el 70 % de las fuentes | B6: =IF(COUNT(Calibracion!$Q$3:$Q$1002)=0,"",ROUND(COUNTIF(Calibracion!$R$3:$R$1002,"Sí")/COUNT(Calibracion!$Q$3:$Q$1002)*100,0)/100) | C6: ≥ 70 % | D6: =IF(B6="","sin datos",IF(ROUND(B6*100,0)>=70,"✓","✕")) | E6: =IF(B6="","Falta pegar el CSV de calibración",ROUND(B6*100,0)&" % en "&COUNT(Calibracion!$Q$3:$Q$1002)&" fuentes")
A7: 2. Utilidad del semáforo según los docentes: promedio de 4 o más (de 5) | B7: =IF(COUNT(Docentes!$R$3:$R$1002)=0,"",ROUND(AVERAGE(Docentes!$R$3:$R$1002),1)) | C7: ≥ 4 de 5 | D7: =IF(B7="","sin datos",IF(B7>=4,"✓","✕")) | E7: =IF(COUNT(Docentes!$Q$3:$Q$1002)=0,"Falta pegar el CSV de opinión docente",IF(B7="","sin respuestas",B7&" de 5"))
A8: 3. Más de la mitad de los docentes lo usaría en clase («Sí, en la próxima tarea» o «Sí, con cambios») | B8: =IF(COUNT(Docentes!$X$3:$X$1002)=0,"",SUM(Docentes!$X$3:$X$1002)/COUNT(Docentes!$X$3:$X$1002)) | C8: más de 50 % | D8: =IF(B8="","sin datos",IF(B8>0.5,"✓","✕")) | E8: =IF(COUNT(Docentes!$Q$3:$Q$1002)=0,"Falta pegar el CSV de opinión docente",IF(B8="","sin respuestas",ROUND(B8*100,0)&" % de "&COUNT(Docentes!$Q$3:$Q$1002)&" docentes"))
A9: 4. Más de la mitad de los estudiantes lo usaría en su próxima tarea («Sí» o «Tal vez») | B9: =IF(COUNT(Estudiantes!$S$3:$S$1002)=0,"",SUM(Estudiantes!$S$3:$S$1002)/COUNT(Estudiantes!$S$3:$S$1002)) | C9: más de 50 % | D9: =IF(B9="","sin datos",IF(B9>0.5,"✓","✕")) | E9: =IF(COUNT(Estudiantes!$L$3:$L$1002)=0,"Falta pegar el CSV de estudiantes",IF(B9="","sin respuestas",ROUND(B9*100,0)&" % de "&COUNT(Estudiantes!$L$3:$L$1002)&" estudiantes"))
A10: Criterios cumplidos | B10: =COUNTIF(D6:D9,"✓")&" de 4"
A11: =IF(AND(COUNT(Calibracion!$Q$3:$Q$1002)>0,B6<>""),IF(ROUND(B6*100,0)<50,"⚠ La coincidencia es menor al 50 %: según el plan, no se propone el piloto hasta corregir el motor y repetir la calibración.",""),"")
A13: Calibración: docentes vs VeriTech
A14: Fuentes calificadas | B14: =COUNT(Calibracion!$Q$3:$Q$1002)
A15: Fuentes en las que coinciden | B15: =COUNTIF(Calibracion!$R$3:$R$1002,"Sí")
A16: Coincidencia | B16: =B6
A17: Docentes que calificaron | B17: =SUM(Calibracion!$Y$3:$Y$1002)
A18: Desacuerdos graves (uno dice «confiable» y el otro «no confiable») | B18: =SUM(Calibracion!$T$3:$T$1002)
A19: Desacuerdos en que VeriTech fue más estricto | B19: =COUNTIF(Calibracion!$S$3:$S$1002,"Más estricto")
A20: Desacuerdos en que VeriTech fue más permisivo | B20: =COUNTIF(Calibracion!$S$3:$S$1002,"Más permisivo")
A22: Matriz: juicio del docente (filas) vs nivel de VeriTech (columnas)
A23: Docente ↓ / VeriTech → | B23: Confiable | C23: Dudosa | D23: No confiable
A24: Confiable | B24: =COUNTIFS(Calibracion!$O$3:$O$1002,2,Calibracion!$P$3:$P$1002,2) | C24: =COUNTIFS(Calibracion!$O$3:$O$1002,2,Calibracion!$P$3:$P$1002,1) | D24: =COUNTIFS(Calibracion!$O$3:$O$1002,2,Calibracion!$P$3:$P$1002,0)
A25: Dudosa | B25: =COUNTIFS(Calibracion!$O$3:$O$1002,1,Calibracion!$P$3:$P$1002,2) | C25: =COUNTIFS(Calibracion!$O$3:$O$1002,1,Calibracion!$P$3:$P$1002,1) | D25: =COUNTIFS(Calibracion!$O$3:$O$1002,1,Calibracion!$P$3:$P$1002,0)
A26: No confiable | B26: =COUNTIFS(Calibracion!$O$3:$O$1002,0,Calibracion!$P$3:$P$1002,2) | C26: =COUNTIFS(Calibracion!$O$3:$O$1002,0,Calibracion!$P$3:$P$1002,1) | D26: =COUNTIFS(Calibracion!$O$3:$O$1002,0,Calibracion!$P$3:$P$1002,0)
A27: En verde: coinciden. Las esquinas «Confiable / No confiable» son los desacuerdos graves.
A29: Señal (en los desacuerdos) | B29: Más estricto: salió «bad» | C29: % | D29: Más permisivo: salió «ok» | E29: %
A30: Autoría | B30: =COUNTIFS(Calibracion!$S$3:$S$1002,"Más estricto",Calibracion!$U$3:$U$1002,"*|Autoría:bad:*") | C30: =IF($B$19=0,"",ROUND(B30/$B$19*100,0)/100) | D30: =COUNTIFS(Calibracion!$S$3:$S$1002,"Más permisivo",Calibracion!$U$3:$U$1002,"*|Autoría:ok:*") | E30: =IF($B$20=0,"",ROUND(D30/$B$20*100,0)/100)
A31: Fecha | B31: =COUNTIFS(Calibracion!$S$3:$S$1002,"Más estricto",Calibracion!$U$3:$U$1002,"*|Fecha:bad:*") | C31: =IF($B$19=0,"",ROUND(B31/$B$19*100,0)/100) | D31: =COUNTIFS(Calibracion!$S$3:$S$1002,"Más permisivo",Calibracion!$U$3:$U$1002,"*|Fecha:ok:*") | E31: =IF($B$20=0,"",ROUND(D31/$B$20*100,0)/100)
A32: Referencias | B32: =COUNTIFS(Calibracion!$S$3:$S$1002,"Más estricto",Calibracion!$U$3:$U$1002,"*|Referencias:bad:*") | C32: =IF($B$19=0,"",ROUND(B32/$B$19*100,0)/100) | D32: =COUNTIFS(Calibracion!$S$3:$S$1002,"Más permisivo",Calibracion!$U$3:$U$1002,"*|Referencias:ok:*") | E32: =IF($B$20=0,"",ROUND(D32/$B$20*100,0)/100)
A33: Dominio | B33: =COUNTIFS(Calibracion!$S$3:$S$1002,"Más estricto",Calibracion!$U$3:$U$1002,"*|Dominio:bad:*") | C33: =IF($B$19=0,"",ROUND(B33/$B$19*100,0)/100) | D33: =COUNTIFS(Calibracion!$S$3:$S$1002,"Más permisivo",Calibracion!$U$3:$U$1002,"*|Dominio:ok:*") | E33: =IF($B$20=0,"",ROUND(D33/$B$20*100,0)/100)
A34: Escritura de relleno | B34: =COUNTIFS(Calibracion!$S$3:$S$1002,"Más estricto",Calibracion!$U$3:$U$1002,"*|Escritura de relleno:bad:*") | C34: =IF($B$19=0,"",ROUND(B34/$B$19*100,0)/100) | D34: =COUNTIFS(Calibracion!$S$3:$S$1002,"Más permisivo",Calibracion!$U$3:$U$1002,"*|Escritura de relleno:ok:*") | E34: =IF($B$20=0,"",ROUND(D34/$B$20*100,0)/100)
A35: Sensacionalismo | B35: =COUNTIFS(Calibracion!$S$3:$S$1002,"Más estricto",Calibracion!$U$3:$U$1002,"*|Sensacionalismo:bad:*") | C35: =IF($B$19=0,"",ROUND(B35/$B$19*100,0)/100) | D35: =COUNTIFS(Calibracion!$S$3:$S$1002,"Más permisivo",Calibracion!$U$3:$U$1002,"*|Sensacionalismo:ok:*") | E35: =IF($B$20=0,"",ROUND(D35/$B$20*100,0)/100)
A36: Certezas sin respaldo | B36: =COUNTIFS(Calibracion!$S$3:$S$1002,"Más estricto",Calibracion!$U$3:$U$1002,"*|Certezas sin respaldo:bad:*") | C36: =IF($B$19=0,"",ROUND(B36/$B$19*100,0)/100) | D36: =COUNTIFS(Calibracion!$S$3:$S$1002,"Más permisivo",Calibracion!$U$3:$U$1002,"*|Certezas sin respaldo:ok:*") | E36: =IF($B$20=0,"",ROUND(D36/$B$20*100,0)/100)
A37: Precisión | B37: =COUNTIFS(Calibracion!$S$3:$S$1002,"Más estricto",Calibracion!$U$3:$U$1002,"*|Precisión:bad:*") | C37: =IF($B$19=0,"",ROUND(B37/$B$19*100,0)/100) | D37: =COUNTIFS(Calibracion!$S$3:$S$1002,"Más permisivo",Calibracion!$U$3:$U$1002,"*|Precisión:ok:*") | E37: =IF($B$20=0,"",ROUND(D37/$B$20*100,0)/100)
A38: Profundidad | B38: =COUNTIFS(Calibracion!$S$3:$S$1002,"Más estricto",Calibracion!$U$3:$U$1002,"*|Profundidad:bad:*") | C38: =IF($B$19=0,"",ROUND(B38/$B$19*100,0)/100) | D38: =COUNTIFS(Calibracion!$S$3:$S$1002,"Más permisivo",Calibracion!$U$3:$U$1002,"*|Profundidad:ok:*") | E38: =IF($B$20=0,"",ROUND(D38/$B$20*100,0)/100)
A39: Cuántas veces cada señal salió mal cuando VeriTech fue más estricto que el docente, y bien cuando fue más permisivo. El % es sobre esos desacuerdos.
A44: Desacuerdos graves (los primeros 10)
A45: URL | B45: Docente dijo | C45: VeriTech dijo | D45: Puntaje | E45: Motivo del docente
A46: =IFERROR(INDEX(Calibracion!$C$3:$C$1002,MATCH(1,Calibracion!$Z$3:$Z$1002,0)),"") | B46: =IFERROR(IFERROR(VLOOKUP(INDEX(Calibracion!$D$3:$D$1002,MATCH(1,Calibracion!$Z$3:$Z$1002,0)),$A$400:$B$435,2,FALSE),INDEX(Calibracion!$D$3:$D$1002,MATCH(1,Calibracion!$Z$3:$Z$1002,0))),"") | C46: =IFERROR(IFERROR(VLOOKUP(INDEX(Calibracion!$F$3:$F$1002,MATCH(1,Calibracion!$Z$3:$Z$1002,0)),$A$400:$B$435,2,FALSE),INDEX(Calibracion!$F$3:$F$1002,MATCH(1,Calibracion!$Z$3:$Z$1002,0))),"") | D46: =IFERROR(INDEX(Calibracion!$E$3:$E$1002,MATCH(1,Calibracion!$Z$3:$Z$1002,0)),"") | E46: =IFERROR(INDEX(Calibracion!$K$3:$K$1002,MATCH(1,Calibracion!$Z$3:$Z$1002,0)),"")
A47: =IFERROR(INDEX(Calibracion!$C$3:$C$1002,MATCH(2,Calibracion!$Z$3:$Z$1002,0)),"") | B47: =IFERROR(IFERROR(VLOOKUP(INDEX(Calibracion!$D$3:$D$1002,MATCH(2,Calibracion!$Z$3:$Z$1002,0)),$A$400:$B$435,2,FALSE),INDEX(Calibracion!$D$3:$D$1002,MATCH(2,Calibracion!$Z$3:$Z$1002,0))),"") | C47: =IFERROR(IFERROR(VLOOKUP(INDEX(Calibracion!$F$3:$F$1002,MATCH(2,Calibracion!$Z$3:$Z$1002,0)),$A$400:$B$435,2,FALSE),INDEX(Calibracion!$F$3:$F$1002,MATCH(2,Calibracion!$Z$3:$Z$1002,0))),"") | D47: =IFERROR(INDEX(Calibracion!$E$3:$E$1002,MATCH(2,Calibracion!$Z$3:$Z$1002,0)),"") | E47: =IFERROR(INDEX(Calibracion!$K$3:$K$1002,MATCH(2,Calibracion!$Z$3:$Z$1002,0)),"")
A48: =IFERROR(INDEX(Calibracion!$C$3:$C$1002,MATCH(3,Calibracion!$Z$3:$Z$1002,0)),"") | B48: =IFERROR(IFERROR(VLOOKUP(INDEX(Calibracion!$D$3:$D$1002,MATCH(3,Calibracion!$Z$3:$Z$1002,0)),$A$400:$B$435,2,FALSE),INDEX(Calibracion!$D$3:$D$1002,MATCH(3,Calibracion!$Z$3:$Z$1002,0))),"") | C48: =IFERROR(IFERROR(VLOOKUP(INDEX(Calibracion!$F$3:$F$1002,MATCH(3,Calibracion!$Z$3:$Z$1002,0)),$A$400:$B$435,2,FALSE),INDEX(Calibracion!$F$3:$F$1002,MATCH(3,Calibracion!$Z$3:$Z$1002,0))),"") | D48: =IFERROR(INDEX(Calibracion!$E$3:$E$1002,MATCH(3,Calibracion!$Z$3:$Z$1002,0)),"") | E48: =IFERROR(INDEX(Calibracion!$K$3:$K$1002,MATCH(3,Calibracion!$Z$3:$Z$1002,0)),"")
...

Sheet Pegar calibracion

Sheet Pegar docentes

Sheet Pegar estudiantes

Sheet Calibracion
A1: docente | B1: area | C1: url | D1: juicio_docente | E1: puntaje_veritech | F1: nivel_veritech | G1: coincide | H1: senales | I1: palabras | J1: version_motor | K1: motivo | L1: consentimiento | M1: juicio docente (normalizado) | N1: nivel VeriTech (normalizado) | O1: Nivel docente (2 confiable · 1 dudosa · 0 no confiable) | P1: Nivel VeriTech (2 confiable · 1 dudosa · 0 no confiable) | Q1: Fila válida (1 = tiene los dos niveles) | R1: ¿Coincide? (Sí/No) | S1: VeriTech fue… | T1: Desacuerdo grave (1 = confiable vs no confiable) | U1: señales (normalizadas) | V1: Área: n.º de aparición | W1: Área: orden | X1: docente (clave) | Y1: Docente nuevo (1) | Z1: Grave n.º
A2: =IFERROR(MATCH("docente",'Pegar calibracion'!$A$1:$BZ$1,0),IFERROR(MATCH("docente[]",'Pegar calibracion'!$A$1:$BZ$1,0),0)) | B2: =IFERROR(MATCH("area",'Pegar calibracion'!$A$1:$BZ$1,0),IFERROR(MATCH("area[]",'Pegar calibracion'!$A$1:$BZ$1,0),0)) | C2: =IFERROR(MATCH("url",'Pegar calibracion'!$A$1:$BZ$1,0),IFERROR(MATCH("url[]",'Pegar calibracion'!$A$1:$BZ$1,0),0)) | D2: =IFERROR(MATCH("juicio_docente",'Pegar calibracion'!$A$1:$BZ$1,0),IFERROR(MATCH("juicio_docente[]",'Pegar calibracion'!$A$1:$BZ$1,0),IFERROR(MATCH("juicio docente",'Pegar calibracion'!$A$1:$BZ$1,0),0))) | E2: =IFERROR(MATCH("puntaje_veritech",'Pegar calibracion'!$A$1:$BZ$1,0),IFERROR(MATCH("puntaje_veritech[]",'Pegar calibracion'!$A$1:$BZ$1,0),IFERROR(MATCH("puntaje veritech",'Pegar calibracion'!$A$1:$BZ$1,0),0))) | F2: =IFERROR(MATCH("nivel_veritech",'Pegar calibracion'!$A$1:$BZ$1,0),IFERROR(MATCH("nivel_veritech[]",'Pegar calibracion'!$A$1:$BZ$1,0),IFERROR(MATCH("nivel veritech",'Pegar calibracion'!$A$1:$BZ$1,0),0))) | G2: =IFERROR(MATCH("coincide",'Pegar calibracion'!$A$1:$BZ$1,0),IFERROR(MATCH("coincide[]",'Pegar calibracion'!$A$1:$BZ$1,0),0)) | H2: =IFERROR(MATCH("senales",'Pegar calibracion'!$A$1:$BZ$1,0),IFERROR(MATCH("senales[]",'Pegar calibracion'!$A$1:$BZ$1,0),0)) | I2: =IFERROR(MATCH("palabras",'Pegar calibracion'!$A$1:$BZ$1,0),IFERROR(MATCH("palabras[]",'Pegar calibracion'!$A$1:$BZ$1,0),0)) | J2: =IFERROR(MATCH("version_motor",'Pegar calibracion'!$A$1:$BZ$1,0),IFERROR(MATCH("version_motor[]",'Pegar calibracion'!$A$1:$BZ$1,0),IFERROR(MATCH("version motor",'Pegar calibracion'!$A$1:$BZ$1,0),0))) | K2: =IFERROR(MATCH("motivo",'Pegar calibracion'!$A$1:$BZ$1,0),IFERROR(MATCH("motivo[]",'Pegar calibracion'!$A$1:$BZ$1,0),0)) | L2: =IFERROR(MATCH("consentimiento",'Pegar calibracion'!$A$1:$BZ$1,0),IFERROR(MATCH("consentimiento[]",'Pegar calibracion'!$A$1:$BZ$1,0),0)) | M2: calculada | N2: calculada | O2: calculada | P2: calculada | Q2: calculada | R2: calculada | S2: calculada | T2: calculada | U2: calculada | V2: calculada | W2: calculada | X2: calculada | Y2: calculada | Z2: calculada
A3: =IF(A$2=0,"",IFERROR(TRIM(INDEX('Pegar calibracion'!$A$1:$BZ$1001,2,A$2)&""),"")) | B3: =IF(B$2=0,"",IFERROR(TRIM(INDEX('Pegar calibracion'!$A$1:$BZ$1001,2,B$2)&""),"")) | C3: =IF(C$2=0,"",IFERROR(TRIM(INDEX('Pegar calibracion'!$A$1:$BZ$1001,2,C$2)&""),"")) | D3: =IF(D$2=0,"",IFERROR(TRIM(INDEX('Pegar calibracion'!$A$1:$BZ$1001,2,D$2)&""),"")) | E3: =IF(E$2=0,"",IFERROR(TRIM(INDEX('Pegar calibracion'!$A$1:$BZ$1001,2,E$2)&""),"")) | F3: =IF(F$2=0,"",IFERROR(TRIM(INDEX('Pegar calibracion'!$A$1:$BZ$1001,2,F$2)&""),"")) | G3: =IF(G$2=0,"",IFERROR(TRIM(INDEX('Pegar calibracion'!$A$1:$BZ$1001,2,G$2)&""),"")) | H3: =IF(H$2=0,"",IFERROR(TRIM(INDEX('Pegar calibracion'!$A$1:$BZ$1001,2,H$2)&""),"")) | ... L3: =IF(L$2=0,"",IFERROR(TRIM(INDEX('Pegar calibracion'!$A$1:$BZ$1001,2,L$2)&""),"")) | M3: =IF(D3="","",SUBSTITUTE(SUBSTITUTE(SUBSTITUTE(SUBSTITUTE(SUBSTITUTE(SUBSTITUTE(SUBSTITUTE(SUBSTITUTE(SUBSTITUTE(SUBSTITUTE(SUBSTITUTE(SUBSTITUTE(LOWER(TRIM(D3)),"á","a"),"é","e"),"í","i"),"ó","o"),"ú","u"),"ü","u"),"ñ","n"),"à","a"),"è","e"),"ì","i"),"ò","o"),"ù","u")) | N3: =IF(F3="","",SUBSTITUTE(SUBSTITUTE(SUBSTITUTE(SUBSTITUTE(SUBSTITUTE(SUBSTITUTE(SUBSTITUTE(SUBSTITUTE(SUBSTITUTE(SUBSTITUTE(SUBSTITUTE(SUBSTITUTE(LOWER(TRIM(F3)),"á","a"),"é","e"),"í","i"),"ó","o"),"ú","u"),"ü","u"),"ñ","n"),"à","a"),"è","e"),"ì","i"),"ò","o"),"ù","u")) | O3: =IF(M3="confiable",2,IF(M3="dudosa",1,IF(M3="no confiable",0,""))) | P3: =IF(N3="confiable",2,IF(N3="dudosa",1,IF(N3="no confiable",0,""))) | Q3: =IF(AND(ISNUMBER(O3),ISNUMBER(P3)),1,"") | R3: =IF(Q3=1,IF(O3=P3,"Sí","No"),"") | S3: =IF(Q3=1,IF(P3<O3,"Más estricto",IF(P3>O3,"Más permisivo","Igual")),"") | T3: =IF(Q3=1,IF(ABS(O3-P3)=2,1,0),"") | U3: =IF(H3="","","|"&SUBSTITUTE(SUBSTITUTE(TRIM(H3)," |","|"),"| ","|")&"|") | V3: =IF(AND(Q3=1,B3<>""),IF(IFERROR(COUNTIFS(B$3:B3,"="&SUBSTITUTE(SUBSTITUTE(SUBSTITUTE(B3,"~","~~"),"*","~*"),"?","~?"),Q$3:Q3,1),0)=1,MAX(V$2:V2)+1,""),"") | W3: =IF(V3="","",COUNTIFS($B$3:$B$1002,"="&SUBSTITUTE(SUBSTITUTE(SUBSTITUTE(B3,"~","~~"),"*","~*"),"?","~?"),$Q$3:$Q$1002,1)*10000-V3) | X3: =IF(Q3=1,IF(SUBSTITUTE(SUBSTITUTE(SUBSTITUTE(SUBSTITUTE(SUBSTITUTE(SUBSTITUTE(SUBSTITUTE(SUBSTITUTE(SUBSTITUTE(SUBSTITUTE(SUBSTITUTE(SUBSTITUTE(LOWER(TRIM(A3)),"á","a"),"é","e"),"í","i"),"ó","o"),"ú","u"),"ü","u"),"ñ","n"),"à","a"),"è","e"),"ì","i"),"ò","o"),"ù","u")="","(sin apodo)",SUBSTITUTE(SUBSTITUTE(SUBSTITUTE(SUBSTITUTE(SUBSTITUTE(SUBSTITUTE(SUBSTITUTE(SUBSTITUTE(SUBSTITUTE(SUBSTITUTE(SUBSTITUTE(SUBSTITUTE(LOWER(TRIM(A3)),"á","a"),"é","e"),"í","i"),"ó","o"),"ú","u"),"ü","u"),"ñ","n"),"à","a"),"è","e"),"ì","i"),"ò","o"),"ù","u")),"") | Y3: =IF(X3="","",IF(IFERROR(COUNTIF(X$3:X3,"="&SUBSTITUTE(SUBSTITUTE(SUBSTITUTE(X3,"~","~~"),"*","~*"),"?","~?")),0)=1,1,"")) | Z3: =IF(T3=1,MAX(Z$2:Z2)+1,"")
A4: =IF(A$2=0,"",IFERROR(TRIM(INDEX('Pegar calibracion'!$A$1:$BZ$1001,3,A$2)&""),"")) | B4: =IF(B$2=0,"",IFERROR(TRIM(INDEX('Pegar calibracion'!$A$1:$BZ$1001,3,B$2)&""),"")) | C4: =IF(C$2=0,"",IFERROR(TRIM(INDEX('Pegar calibracion'!$A$1:$BZ$1001,3,C$2)&""),"")) | D4: =IF(D$2=0,"",IFERROR(TRIM(INDEX('Pegar calibracion'!$A$1:$BZ$1001,3,D$2)&""),"")) | E4: =IF(E$2=0,"",IFERROR(TRIM(INDEX('Pegar calibracion'!$A$1:$BZ$1001,3,E$2)&""),"")) | F4: =IF(F$2=0,"",IFERROR(TRIM(INDEX('Pegar calibracion'!$A$1:$BZ$1001,3,F$2)&""),"")) | G4: =IF(G$2=0,"",IFERROR(TRIM(INDEX('Pegar calibracion'!$A$1:$BZ$1001,3,G$2)&""),"")) | H4: =IF(H$2=0,"",IFERROR(TRIM(INDEX('Pegar calibracion'!$A$1:$BZ$1001,3,H$2)&""),"")) | ... L4: =IF(L$2=0,"",IFERROR(TRIM(INDEX('Pegar calibracion'!$A$1:$BZ$1001,3,L$2)&""),"")) | M4: =IF(D4="","",SUBSTITUTE(SUBSTITUTE(SUBSTITUTE(SUBSTITUTE(SUBSTITUTE(SUBSTITUTE(SUBSTITUTE(SUBSTITUTE(SUBSTITUTE(SUBSTITUTE(SUBSTITUTE(SUBSTITUTE(LOWER(TRIM(D4)),"á","a"),"é","e"),"í","i"),"ó","o"),"ú","u"),"ü","u"),"ñ","n"),"à","a"),"è","e"),"ì","i"),"ò","o"),"ù","u")) | N4: =IF(F4="","",SUBSTITUTE(SUBSTITUTE(SUBSTITUTE(SUBSTITUTE(SUBSTITUTE(SUBSTITUTE(SUBSTITUTE(SUBSTITUTE(SUBSTITUTE(SUBSTITUTE(SUBSTITUTE(SUBSTITUTE(LOWER(TRIM(F4)),"á","a"),"é","e"),"í","i"),"ó","o"),"ú","u"),"ü","u"),"ñ","n"),"à","a"),"è","e"),"ì","i"),"ò","o"),"ù","u")) | O4: =IF(M4="confiable",2,IF(M4="dudosa",1,IF(M4="no confiable",0,""))) | P4: =IF(N4="confiable",2,IF(N4="dudosa",1,IF(N4="no confiable",0,""))) | Q4: =IF(AND(ISNUMBER(O4),ISNUMBER(P4)),1,"") | R4: =IF(Q4=1,IF(O4=P4,"Sí","No"),"") | S4: =IF(Q4=1,IF(P4<O4,"Más estricto",IF(P4>O4,"Más permisivo","Igual")),"") | T4: =IF(Q4=1,IF(ABS(O4-P4)=2,1,0),"") | U4: =IF(H4="","","|"&SUBSTITUTE(SUBSTITUTE(TRIM(H4)," |","|"),"| ","|")&"|") | V4: =IF(AND(Q4=1,B4<>""),IF(IFERROR(COUNTIFS(B$3:B4,"="&SUBSTITUTE(SUBSTITUTE(SUBSTITUTE(B4,"~","~~"),"*","~*"),"?","~?"),Q$3:Q4,1),0)=1,MAX(V$2:V3)+1,""),"") | W4: =IF(V4="","",COUNTIFS($B$3:$B$1002,"="&SUBSTITUTE(SUBSTITUTE(SUBSTITUTE(B4,"~","~~"),"*","~*"),"?","~?"),$Q$3:$Q$1002,1)*10000-V4) | X4: =IF(Q4=1,IF(SUBSTITUTE(SUBSTITUTE(SUBSTITUTE(SUBSTITUTE(SUBSTITUTE(SUBSTITUTE(SUBSTITUTE(SUBSTITUTE(SUBSTITUTE(SUBSTITUTE(SUBSTITUTE(SUBSTITUTE(LOWER(TRIM(A4)),"á","a"),"é","e"),"í","i"),"ó","o"),"ú","u"),"ü","u"),"ñ","n"),"à","a"),"è","e"),"ì","i"),"ò","o"),"ù","u")="","(sin apodo)",SUBSTITUTE(SUBSTITUTE(SUBSTITUTE(SUBSTITUTE(SUBSTITUTE(SUBSTITUTE(SUBSTITUTE(SUBSTITUTE(SUBSTITUTE(SUBSTITUTE(SUBSTITUTE(SUBSTITUTE(LOWER(TRIM(A4)),"á","a"),"é","e"),"í","i"),"ó","o"),"ú","u"),"ü","u"),"ñ","n"),"à","a"),"è","e"),"ì","i"),"ò","o"),"ù","u")),"") | Y4: =IF(X4="","",IF(IFERROR(COUNTIF(X$3:X4,"="&SUBSTITUTE(SUBSTITUTE(SUBSTITUTE(X4,"~","~~"),"*","~*"),"?","~?")),0)=1,1,"")) | Z4: =IF(T4=1,MAX(Z$2:Z3)+1,"")
A5: =IF(A$2=0,"",IFERROR(TRIM(INDEX('Pegar calibracion'!$A$1:$BZ$1001,4,A$2)&""),"")) | B5: =IF(B$2=0,"",IFERROR(TRIM(INDEX('Pegar calibracion'!$A$1:$BZ$1001,4,B$2)&""),"")) | C5: =IF(C$2=0,"",IFERROR(TRIM(INDEX('Pegar calibracion'!$A$1:$BZ$1001,4,C$2)&""),"")) | D5: =IF(D$2=0,"",IFERROR(TRIM(INDEX('Pegar calibracion'!$A$1:$BZ$1001,4,D$2)&""),"")) | E5: =IF(E$2=0,"",IFERROR(TRIM(INDEX('Pegar calibracion'!$A$1:$BZ$1001,4,E$2)&""),"")) | F5: =IF(F$2=0,"",IFERROR(TRIM(INDEX('Pegar calibracion'!$A$1:$BZ$1001,4,F$2)&""),"")) | G5: =IF(G$2=0,"",IFERROR(TRIM(INDEX('Pegar calibracion'!$A$1:$BZ$1001,4,G$2)&""),"")) | H5: =IF(H$2=0,"",IFERROR(TRIM(INDEX('Pegar calibracion'!$A$1:$BZ$1001,4,H$2)&""),"")) | ... L5: =IF(L$2=0,"",IFERROR(TRIM(INDEX('Pegar calibracion'!$A$1:$BZ$1001,4,L$2)&""),"")) | M5: =IF(D5="","",SUBSTITUTE(SUBSTITUTE(SUBSTITUTE(SUBSTITUTE(SUBSTITUTE(SUBSTITUTE(SUBSTITUTE(SUBSTITUTE(SUBSTITUTE(SUBSTITUTE(SUBSTITUTE(SUBSTITUTE(LOWER(TRIM(D5)),"á","a"),"é","e"),"í","i"),"ó","o"),"ú","u"),"ü","u"),"ñ","n"),"à","a"),"è","e"),"ì","i"),"ò","o"),"ù","u")) | N5: =IF(F5="","",SUBSTITUTE(SUBSTITUTE(SUBSTITUTE(SUBSTITUTE(SUBSTITUTE(SUBSTITUTE(SUBSTITUTE(SUBSTITUTE(SUBSTITUTE(SUBSTITUTE(SUBSTITUTE(SUBSTITUTE(LOWER(TRIM(F5)),"á","a"),"é","e"),"í","i"),"ó","o"),"ú","u"),"ü","u"),"ñ","n"),"à","a"),"è","e"),"ì","i"),"ò","o"),"ù","u")) | O5: =IF(M5="confiable",2,IF(M5="dudosa",1,IF(M5="no confiable",0,""))) | P5: =IF(N5="confiable",2,IF(N5="dudosa",1,IF(N5="no confiable",0,""))) | Q5: =IF(AND(ISNUMBER(O5),ISNUMBER(P5)),1,"") | R5: =IF(Q5=1,IF(O5=P5,"Sí","No"),"") | S5: =IF(Q5=1,IF(P5<O5,"Más estricto",IF(P5>O5,"Más permisivo","Igual")),"") | T5: =IF(Q5=1,IF(ABS(O5-P5)=2,1,0),"") | U5: =IF(H5="","","|"&SUBSTITUTE(SUBSTITUTE(TRIM(H5)," |","|"),"| ","|")&"|") | V5: =IF(AND(Q5=1,B5<>""),IF(IFERROR(COUNTIFS(B$3:B5,"="&SUBSTITUTE(SUBSTITUTE(SUBSTITUTE(B5,"~","~~"),"*","~*"),"?","~?"),Q$3:Q5,1),0)=1,MAX(V$2:V4)+1,""),"") | W5: =IF(V5="","",COUNTIFS($B$3:$B$1002,"="&SUBSTITUTE(SUBSTITUTE(SUBSTITUTE(B5,"~","~~"),"*","~*"),"?","~?"),$Q$3:$Q$1002,1)*10000-V5) | X5: =IF(Q5=1,IF(SUBSTITUTE(SUBSTITUTE(SUBSTITUTE(SUBSTITUTE(SUBSTITUTE(SUBSTITUTE(SUBSTITUTE(SUBSTITUTE(SUBSTITUTE(SUBSTITUTE(SUBSTITUTE(SUBSTITUTE(LOWER(TRIM(A5)),"á","a"),"é","e"),"í","i"),"ó","o"),"ú","u"),"ü","u"),"ñ","n"),"à","a"),"è","e"),"ì","i"),"ò","o"),"ù","u")="","(sin apodo)",SUBSTITUTE(SUBSTITUTE(SUBSTITUTE(SUBSTITUTE(SUBSTITUTE(SUBSTITUTE(SUBSTITUTE(SUBSTITUTE(SUBSTITUTE(SUBSTITUTE(SUBSTITUTE(SUBSTITUTE(LOWER(TRIM(A5)),"á","a"),"é","e"),"í","i"),"ó","o"),"ú","u"),"ü","u"),"ñ","n"),"à","a"),"è","e"),"ì","i"),"ò","o"),"ù","u")),"") | Y5: =IF(X5="","",IF(IFERROR(COUNTIF(X$3:X5,"="&SUBSTITUTE(SUBSTITUTE(SUBSTITUTE(X5,"~","~~"),"*","~*"),"?","~?")),0)=1,1,"")) | Z5: =IF(T5=1,MAX(Z$2:Z4)+1,"")
A6: =IF(A$2=0,"",IFERROR(TRIM(INDEX('Pegar calibracion'!$A$1:$BZ$1001,5,A$2)&""),"")) | B6: =IF(B$2=0,"",IFERROR(TRIM(INDEX('Pegar calibracion'!$A$1:$BZ$1001,5,B$2)&""),"")) | C6: =IF(C$2=0,"",IFERROR(TRIM(INDEX('Pegar calibracion'!$A$1:$BZ$1001,5,C$2)&""),"")) | D6: =IF(D$2=0,"",IFERROR(TRIM(INDEX('Pegar calibracion'!$A$1:$BZ$1001,5,D$2)&""),"")) | E6: =IF(E$2=0,"",IFERROR(TRIM(INDEX('Pegar calibracion'!$A$1:$BZ$1001,5,E$2)&""),"")) | F6: =IF(F$2=0,"",IFERROR(TRIM(INDEX('Pegar calibracion'!$A$1:$BZ$1001,5,F$2)&""),"")) | G6: =IF(G$2=0,"",IFERROR(TRIM(INDEX('Pegar calibracion'!$A$1:$BZ$1001,5,G$2)&""),"")) | H6: =IF(H$2=0,"",IFERROR(TRIM(INDEX('Pegar calibracion'!$A$1:$BZ$1001,5,H$2)&""),"")) | ... L6: =IF(L$2=0,"",IFERROR(TRIM(INDEX('Pegar calibracion'!$A$1:$BZ$1001,5,L$2)&""),"")) | M6: =IF(D6="","",SUBSTITUTE(SUBSTITUTE(SUBSTITUTE(SUBSTITUTE(SUBSTITUTE(SUBSTITUTE(SUBSTITUTE(SUBSTITUTE(SUBSTITUTE(SUBSTITUTE(SUBSTITUTE(SUBSTITUTE(LOWER(TRIM(D6)),"á","a"),"é","e"),"í","i"),"ó","o"),"ú","u"),"ü","u"),"ñ","n"),"à","a"),"è","e"),"ì","i"),"ò","o"),"ù","u")) | N6: =IF(F6="","",SUBSTITUTE(SUBSTITUTE(SUBSTITUTE(SUBSTITUTE(SUBSTITUTE(SUBSTITUTE(SUBSTITUTE(SUBSTITUTE(SUBSTITUTE(SUBSTITUTE(SUBSTITUTE(SUBSTITUTE(LOWER(TRIM(F6)),"á","a"),"é","e"),"í","i"),"ó","o"),"ú","u"),"ü","u"),"ñ","n"),"à","a"),"è","e"),"ì","i"),"ò","o"),"ù","u")) | O6: =IF(M6="confiable",2,IF(M6="dudosa",1,IF(M6="no confiable",0,""))) | P6: =IF(N6="confiable",2,IF(N6="dudosa",1,IF(N6="no confiable",0,""))) | Q6: =IF(AND(ISNUMBER(O6),ISNUMBER(P6)),1,"") | R6: =IF(Q6=1,IF(O6=P6,"Sí","No"),"") | S6: =IF(Q6=1,IF(P6<O6,"Más estricto",IF(P6>O6,"Más permisivo","Igual")),"") | T6: =IF(Q6=1,IF(ABS(O6-P6)=2,1,0),"") | U6: =IF(H6="","","|"&SUBSTITUTE(SUBSTITUTE(TRIM(H6)," |","|"),"| ","|")&"|") | V6: =IF(AND(Q6=1,B6<>""),IF(IFERROR(COUNTIFS(B$3:B6,"="&SUBSTITUTE(SUBSTITUTE(SUBSTITUTE(B6,"~","~~"),"*","~*"),"?","~?"),Q$3:Q6,1),0)=1,MAX(V$2:V5)+1,""),"") | W6: =IF(V6="","",COUNTIFS($B$3:$B$1002,"="&SUBSTITUTE(SUBSTITUTE(SUBSTITUTE(B6,"~","~~"),"*","~*"),"?","~?"),$Q$3:$Q$1002,1)*10000-V6) | X6: =IF(Q6=1,IF(SUBSTITUTE(SUBSTITUTE(SUBSTITUTE(SUBSTITUTE(SUBSTITUTE(SUBSTITUTE(SUBSTITUTE(SUBSTITUTE(SUBSTITUTE(SUBSTITUTE(SUBSTITUTE(SUBSTITUTE(LOWER(TRIM(A6)),"á","a"),"é","e"),"í","i"),"ó","o"),"ú","u"),"ü","u"),"ñ","n"),"à","a"),"è","e"),"ì","i"),"ò","o"),"ù","u")="","(sin apodo)",SUBSTITUTE(SUBSTITUTE(SUBSTITUTE(SUBSTITUTE(SUBSTITUTE(SUBSTITUTE(SUBSTITUTE(SUBSTITUTE(SUBSTITUTE(SUBSTITUTE(SUBSTITUTE(SUBSTITUTE(LOWER(TRIM(A6)),"á","a"),"é","e"),"í","i"),"ó","o"),"ú","u"),"ü","u"),"ñ","n"),"à","a"),"è","e"),"ì","i"),"ò","o"),"ù","u")),"") | Y6: =IF(X6="","",IF(IFERROR(COUNTIF(X$3:X6,"="&SUBSTITUTE(SUBSTITUTE(SUBSTITUTE(X6,"~","~~"),"*","~*"),"?","~?")),0)=1,1,"")) | Z6: =IF(T6=1,MAX(Z$2:Z5)+1,"")
A7: =IF(A$2=0,"",IFERROR(TRIM(INDEX('Pegar calibracion'!$A$1:$BZ$1001,6,A$2)&""),"")) | B7: =IF(B$2=0,"",IFERROR(TRIM(INDEX('Pegar calibracion'!$A$1:$BZ$1001,6,B$2)&""),"")) | C7: =IF(C$2=0,"",IFERROR(TRIM(INDEX('Pegar calibracion'!$A$1:$BZ$1001,6,C$2)&""),"")) | D7: =IF(D$2=0,"",IFERROR(TRIM(INDEX('Pegar calibracion'!$A$1:$BZ$1001,6,D$2)&""),"")) | E7: =IF(E$2=0,"",IFERROR(TRIM(INDEX('Pegar calibracion'!$A$1:$BZ$1001,6,E$2)&""),"")) | F7: =IF(F$2=0,"",IFERROR(TRIM(INDEX('Pegar calibracion'!$A$1:$BZ$1001,6,F$2)&""),"")) | G7: =IF(G$2=0,"",IFERROR(TRIM(INDEX('Pegar calibracion'!$A$1:$BZ$1001,6,G$2)&""),"")) | H7: =IF(H$2=0,"",IFERROR(TRIM(INDEX('Pegar calibracion'!$A$1:$BZ$1001,6,H$2)&""),"")) | ... L7: =IF(L$2=0,"",IFERROR(TRIM(INDEX('Pegar calibracion'!$A$1:$BZ$1001,6,L$2)&""),"")) | M7: =IF(D7="","",SUBSTITUTE(SUBSTITUTE(SUBSTITUTE(SUBSTITUTE(SUBSTITUTE(SUBSTITUTE(SUBSTITUTE(SUBSTITUTE(SUBSTITUTE(SUBSTITUTE(SUBSTITUTE(SUBSTITUTE(LOWER(TRIM(D7)),"á","a"),"é","e"),"í","i"),"ó","o"),"ú","u"),"ü","u"),"ñ","n"),"à","a"),"è","e"),"ì","i"),"ò","o"),"ù","u")) | N7: =IF(F7="","",SUBSTITUTE(SUBSTITUTE(SUBSTITUTE(SUBSTITUTE(SUBSTITUTE(SUBSTITUTE(SUBSTITUTE(SUBSTITUTE(SUBSTITUTE(SUBSTITUTE(SUBSTITUTE(SUBSTITUTE(LOWER(TRIM(F7)),"á","a"),"é","e"),"í","i"),"ó","o"),"ú","u"),"ü","u"),"ñ","n"),"à","a"),"è","e"),"ì","i"),"ò","o"),"ù","u")) | O7: =IF(M7="confiable",2,IF(M7="dudosa",1,IF(M7="no confiable",0,""))) | P7: =IF(N7="confiable",2,IF(N7="dudosa",1,IF(N7="no confiable",0,""))) | Q7: =IF(AND(ISNUMBER(O7),ISNUMBER(P7)),1,"") | R7: =IF(Q7=1,IF(O7=P7,"Sí","No"),"") | S7: =IF(Q7=1,IF(P7<O7,"Más estricto",IF(P7>O7,"Más permisivo","Igual")),"") | T7: =IF(Q7=1,IF(ABS(O7-P7)=2,1,0),"") | U7: =IF(H7="","","|"&SUBSTITUTE(SUBSTITUTE(TRIM(H7)," |","|"),"| ","|")&"|") | V7: =IF(AND(Q7=1,B7<>""),IF(IFERROR(COUNTIFS(B$3:B7,"="&SUBSTITUTE(SUBSTITUTE(SUBSTITUTE(B7,"~","~~"),"*","~*"),"?","~?"),Q$3:Q7,1),0)=1,MAX(V$2:V6)+1,""),"") | W7: =IF(V7="","",COUNTIFS($B$3:$B$1002,"="&SUBSTITUTE(SUBSTITUTE(SUBSTITUTE(B7,"~","~~"),"*","~*"),"?","~?"),$Q$3:$Q$1002,1)*10000-V7) | X7: =IF(Q7=1,IF(SUBSTITUTE(SUBSTITUTE(SUBSTITUTE(SUBSTITUTE(SUBSTITUTE(SUBSTITUTE(SUBSTITUTE(SUBSTITUTE(SUBSTITUTE(SUBSTITUTE(SUBSTITUTE(SUBSTITUTE(LOWER(TRIM(A7)),"á","a"),"é","e"),"í","i"),"ó","o"),"ú","u"),"ü","u"),"ñ","n"),"à","a"),"è","e"),"ì","i"),"ò","o"),"ù","u")="","(sin apodo)",SUBSTITUTE(SUBSTITUTE(SUBSTITUTE(SUBSTITUTE(SUBSTITUTE(SUBSTITUTE(SUBSTITUTE(SUBSTITUTE(SUBSTITUTE(SUBSTITUTE(SUBSTITUTE(SUBSTITUTE(LOWER(TRIM(A7)),"á","a"),"é","e"),"í","i"),"ó","o"),"ú","u"),"ü","u"),"ñ","n"),"à","a"),"è","e"),"ì","i"),"ò","o"),"ù","u")),"") | Y7: =IF(X7="","",IF(IFERROR(COUNTIF(X$3:X7,"="&SUBSTITUTE(SUBSTITUTE(SUBSTITUTE(X7,"~","~~"),"*","~*"),"?","~?")),0)=1,1,"")) | Z7: =IF(T7=1,MAX(Z$2:Z6)+1,"")
A8: =IF(A$2=0,"",IFERROR(TRIM(INDEX('Pegar calibracion'!$A$1:$BZ$1001,7,A$2)&""),"")) | B8: =IF(B$2=0,"",IFERROR(TRIM(INDEX('Pegar calibracion'!$A$1:$BZ$1001,7,B$2)&""),"")) | C8: =IF(C$2=0,"",IFERROR(TRIM(INDEX('Pegar calibracion'!$A$1:$BZ$1001,7,C$2)&""),"")) | D8: =IF(D$2=0,"",IFERROR(TRIM(INDEX('Pegar calibracion'!$A$1:$BZ$1001,7,D$2)&""),"")) | E8: =IF(E$2=0,"",IFERROR(TRIM(INDEX('Pegar calibracion'!$A$1:$BZ$1001,7,E$2)&""),"")) | F8: =IF(F$2=0,"",IFERROR(TRIM(INDEX('Pegar calibracion'!$A$1:$BZ$1001,7,F$2)&""),"")) | G8: =IF(G$2=0,"",IFERROR(TRIM(INDEX('Pegar calibracion'!$A$1:$BZ$1001,7,G$2)&""),"")) | H8: =IF(H$2=0,"",IFERROR(TRIM(INDEX('Pegar calibracion'!$A$1:$BZ$1001,7,H$2)&""),"")) | ... L8: =IF(L$2=0,"",IFERROR(TRIM(INDEX('Pegar calibracion'!$A$1:$BZ$1001,7,L$2)&""),"")) | M8: =IF(D8="","",SUBSTITUTE(SUBSTITUTE(SUBSTITUTE(SUBSTITUTE(SUBSTITUTE(SUBSTITUTE(SUBSTITUTE(SUBSTITUTE(SUBSTITUTE(SUBSTITUTE(SUBSTITUTE(SUBSTITUTE(LOWER(TRIM(D8)),"á","a"),"é","e"),"í","i"),"ó","o"),"ú","u"),"ü","u"),"ñ","n"),"à","a"),"è","e"),"ì","i"),"ò","o"),"ù","u")) | N8: =IF(F8="","",SUBSTITUTE(SUBSTITUTE(SUBSTITUTE(SUBSTITUTE(SUBSTITUTE(SUBSTITUTE(SUBSTITUTE(SUBSTITUTE(SUBSTITUTE(SUBSTITUTE(SUBSTITUTE(SUBSTITUTE(LOWER(TRIM(F8)),"á","a"),"é","e"),"í","i"),"ó","o"),"ú","u"),"ü","u"),"ñ","n"),"à","a"),"è","e"),"ì","i"),"ò","o"),"ù","u")) | O8: =IF(M8="confiable",2,IF(M8="dudosa",1,IF(M8="no confiable",0,""))) | P8: =IF(N8="confiable",2,IF(N8="dudosa",1,IF(N8="no confiable",0,""))) | Q8: =IF(AND(ISNUMBER(O8),ISNUMBER(P8)),1,"") | R8: =IF(Q8=1,IF(O8=P8,"Sí","No"),"") | S8: =IF(Q8=1,IF(P8<O8,"Más estricto",IF(P8>O8,"Más permisivo","Igual")),"") | T8: =IF(Q8=1,IF(ABS(O8-P8)=2,1,0),"") | U8: =IF(H8="","","|"&SUBSTITUTE(SUBSTITUTE(TRIM(H8)," |","|"),"| ","|")&"|") | V8: =IF(AND(Q8=1,B8<>""),IF(IFERROR(COUNTIFS(B$3:B8,"="&SUBSTITUTE(SUBSTITUTE(SUBSTITUTE(B8,"~","~~"),"*","~*"),"?","~?"),Q$3:Q8,1),0)=1,MAX(V$2:V7)+1,""),"") | W8: =IF(V8="","",COUNTIFS($B$3:$B$1002,"="&SUBSTITUTE(SUBSTITUTE(SUBSTITUTE(B8,"~","~~"),"*","~*"),"?","~?"),$Q$3:$Q$1002,1)*10000-V8) | X8: =IF(Q8=1,IF(SUBSTITUTE(SUBSTITUTE(SUBSTITUTE(SUBSTITUTE(SUBSTITUTE(SUBSTITUTE(SUBSTITUTE(SUBSTITUTE(SUBSTITUTE(SUBSTITUTE(SUBSTITUTE(SUBSTITUTE(LOWER(TRIM(A8)),"á","a"),"é","e"),"í","i"),"ó","o"),"ú","u"),"ü","u"),"ñ","n"),"à","a"),"è","e"),"ì","i"),"ò","o"),"ù","u")="","(sin apodo)",SUBSTITUTE(SUBSTITUTE(SUBSTITUTE(SUBSTITUTE(SUBSTITUTE(SUBSTITUTE(SUBSTITUTE(SUBSTITUTE(SUBSTITUTE(SUBSTITUTE(SUBSTITUTE(SUBSTITUTE(LOWER(TRIM(A8)),"á","a"),"é","e"),"í","i"),"ó","o"),"ú","u"),"ü","u"),"ñ","n"),"à","a"),"è","e"),"ì","i"),"ò","o"),"ù","u")),"") | Y8: =IF(X8="","",IF(IFERROR(COUNTIF(X$3:X8,"="&SUBSTITUTE(SUBSTITUTE(SUBSTITUTE(X8,"~","~~"),"*","~*"),"?","~?")),0)=1,1,"")) | Z8: =IF(T8=1,MAX(Z$2:Z7)+1,"")
A9: =IF(A$2=0,"",IFERROR(TRIM(INDEX('Pegar calibracion'!$A$1:$BZ$1001,8,A$2)&""),"")) | B9: =IF(B$2=0,"",IFERROR(TRIM(INDEX('Pegar calibracion'!$A$1:$BZ$1001,8,B$2)&""),"")) | C9: =IF(C$2=0,"",IFERROR(TRIM(INDEX('Pegar calibracion'!$A$1:$BZ$1001,8,C$2)&""),"")) | D9: =IF(D$2=0,"",IFERROR(TRIM(INDEX('Pegar calibracion'!$A$1:$BZ$1001,8,D$2)&""),"")) | E9: =IF(E$2=0,"",IFERROR(TRIM(INDEX('Pegar calibracion'!$A$1:$BZ$1001,8,E$2)&""),"")) | F9: =IF(F$2=0,"",IFERROR(TRIM(INDEX('Pegar calibracion'!$A$1:$BZ$1001,8,F$2)&""),"")) | G9: =IF(G$2=0,"",IFERROR(TRIM(INDEX('Pegar calibracion'!$A$1:$BZ$1001,8,G$2)&""),"")) | H9: =IF(H$2=0,"",IFERROR(TRIM(INDEX('Pegar calibracion'!$A$1:$BZ$1001,8,H$2)&""),"")) | ... L9: =IF(L$2=0,"",IFERROR(TRIM(INDEX('Pegar calibracion'!$A$1:$BZ$1001,8,L$2)&""),"")) | M9: =IF(D9="","",SUBSTITUTE(SUBSTITUTE(SUBSTITUTE(SUBSTITUTE(SUBSTITUTE(SUBSTITUTE(SUBSTITUTE(SUBSTITUTE(SUBSTITUTE(SUBSTITUTE(SUBSTITUTE(SUBSTITUTE(LOWER(TRIM(D9)),"á","a"),"é","e"),"í","i"),"ó","o"),"ú","u"),"ü","u"),"ñ","n"),"à","a"),"è","e"),"ì","i"),"ò","o"),"ù","u")) | N9: =IF(F9="","",SUBSTITUTE(SUBSTITUTE(SUBSTITUTE(SUBSTITUTE(SUBSTITUTE(SUBSTITUTE(SUBSTITUTE(SUBSTITUTE(SUBSTITUTE(SUBSTITUTE(SUBSTITUTE(SUBSTITUTE(LOWER(TRIM(F9)),"á","a"),"é","e"),"í","i"),"ó","o"),"ú","u"),"ü","u"),"ñ","n"),"à","a"),"è","e"),"ì","i"),"ò","o"),"ù","u")) | O9: =IF(M9="confiable",2,IF(M9="dudosa",1,IF(M9="no confiable",0,""))) | P9: =IF(N9="confiable",2,IF(N9="dudosa",1,IF(N9="no confiable",0,""))) | Q9: =IF(AND(ISNUMBER(O9),ISNUMBER(P9)),1,"") | R9: =IF(Q9=1,IF(O9=P9,"Sí","No"),"") | S9: =IF(Q9=1,IF(P9<O9,"Más estricto",IF(P9>O9,"Más permisivo","Igual")),"") | T9: =IF(Q9=1,IF(ABS(O9-P9)=2,1,0),"") | U9: =IF(H9="","","|"&SUBSTITUTE(SUBSTITUTE(TRIM(H9)," |","|"),"| ","|")&"|") | V9: =IF(AND(Q9=1,B9<>""),IF(IFERROR(COUNTIFS(B$3:B9,"="&SUBSTITUTE(SUBSTITUTE(SUBSTITUTE(B9,"~","~~"),"*","~*"),"?","~?"),Q$3:Q9,1),0)=1,MAX(V$2:V8)+1,""),"") | W9: =IF(V9="","",COUNTIFS($B$3:$B$1002,"="&SUBSTITUTE(SUBSTITUTE(SUBSTITUTE(B9,"~","~~"),"*","~*"),"?","~?"),$Q$3:$Q$1002,1)*10000-V9) | X9: =IF(Q9=1,IF(SUBSTITUTE(SUBSTITUTE(SUBSTITUTE(SUBSTITUTE(SUBSTITUTE(SUBSTITUTE(SUBSTITUTE(SUBSTITUTE(SUBSTITUTE(SUBSTITUTE(SUBSTITUTE(SUBSTITUTE(LOWER(TRIM(A9)),"á","a"),"é","e"),"í","i"),"ó","o"),"ú","u"),"ü","u"),"ñ","n"),"à","a"),"è","e"),"ì","i"),"ò","o"),"ù","u")="","(sin apodo)",SUBSTITUTE(SUBSTITUTE(SUBSTITUTE(SUBSTITUTE(SUBSTITUTE(SUBSTITUTE(SUBSTITUTE(SUBSTITUTE(SUBSTITUTE(SUBSTITUTE(SUBSTITUTE(SUBSTITUTE(LOWER(TRIM(A9)),"á","a"),"é","e"),"í","i"),"ó","o"),"ú","u"),"ü","u"),"ñ","n"),"à","a"),"è","e"),"ì","i"),"ò","o"),"ù","u")),"") | Y9: =IF(X9="","",IF(IFERROR(COUNTIF(X$3:X9,"="&SUBSTITUTE(SUBSTITUTE(SUBSTITUTE(X9,"~","~~"),"*","~*"),"?","~?")),0)=1,1,"")) | Z9: =IF(T9=1,MAX(Z$2:Z8)+1,"")
A10: =IF(A$2=0,"",IFERROR(TRIM(INDEX('Pegar calibracion'!$A$1:$BZ$1001,9,A$2)&""),"")) | B10: =IF(B$2=0,"",IFERROR(TRIM(INDEX('Pegar calibracion'!$A$1:$BZ$1001,9,B$2)&""),"")) | C10: =IF(C$2=0,"",IFERROR(TRIM(INDEX('Pegar calibracion'!$A$1:$BZ$1001,9,C$2)&""),"")) | D10: =IF(D$2=0,"",IFERROR(TRIM(INDEX('Pegar calibracion'!$A$1:$BZ$1001,9,D$2)&""),"")) | E10: =IF(E$2=0,"",IFERROR(TRIM(INDEX('Pegar calibracion'!$A$1:$BZ$1001,9,E$2)&""),"")) | F10: =IF(F$2=0,"",IFERROR(TRIM(INDEX('Pegar calibracion'!$A$1:$BZ$1001,9,F$2)&""),"")) | G10: =IF(G$2=0,"",IFERROR(TRIM(INDEX('Pegar calibracion'!$A$1:$BZ$1001,9,G$2)&""),"")) | H10: =IF(H$2=0,"",IFERROR(TRIM(INDEX('Pegar calibracion'!$A$1:$BZ$1001,9,H$2)&""),"")) | ... L10: =IF(L$2=0,"",IFERROR(TRIM(INDEX('Pegar calibracion'!$A$1:$BZ$1001,9,L$2)&""),"")) | M10: =IF(D10="","",SUBSTITUTE(SUBSTITUTE(SUBSTITUTE(SUBSTITUTE(SUBSTITUTE(SUBSTITUTE(SUBSTITUTE(SUBSTITUTE(SUBSTITUTE(SUBSTITUTE(SUBSTITUTE(SUBSTITUTE(LOWER(TRIM(D10)),"á","a"),"é","e"),"í","i"),"ó","o"),"ú","u"),"ü","u"),"ñ","n"),"à","a"),"è","e"),"ì","i"),"ò","o"),"ù","u")) | N10: =IF(F10="","",SUBSTITUTE(SUBSTITUTE(SUBSTITUTE(SUBSTITUTE(SUBSTITUTE(SUBSTITUTE(SUBSTITUTE(SUBSTITUTE(SUBSTITUTE(SUBSTITUTE(SUBSTITUTE(SUBSTITUTE(LOWER(TRIM(F10)),"á","a"),"é","e"),"í","i"),"ó","o"),"ú","u"),"ü","u"),"ñ","n"),"à","a"),"è","e"),"ì","i"),"ò","o"),"ù","u")) | O10: =IF(M10="confiable",2,IF(M10="dudosa",1,IF(M10="no confiable",0,""))) | P10: =IF(N10="confiable",2,IF(N10="dudosa",1,IF(N10="no confiable",0,""))) | Q10: =IF(AND(ISNUMBER(O10),ISNUMBER(P10)),1,"") | R10: =IF(Q10=1,IF(O10=P10,"Sí","No"),"") | S10: =IF(Q10=1,IF(P10<O10,"Más estricto",IF(P10>O10,"Más permisivo","Igual")),"") | T10: =IF(Q10=1,IF(ABS(O10-P10)=2,1,0),"") | U10: =IF(H10="","","|"&SUBSTITUTE(SUBSTITUTE(TRIM(H10)," |","|"),"| ","|")&"|") | V10: =IF(AND(Q10=1,B10<>""),IF(IFERROR(COUNTIFS(B$3:B10,"="&SUBSTITUTE(SUBSTITUTE(SUBSTITUTE(B10,"~","~~"),"*","~*"),"?","~?"),Q$3:Q10,1),0)=1,MAX(V$2:V9)+1,""),"") | W10: =IF(V10="","",COUNTIFS($B$3:$B$1002,"="&SUBSTITUTE(SUBSTITUTE(SUBSTITUTE(B10,"~","~~"),"*","~*"),"?","~?"),$Q$3:$Q$1002,1)*10000-V10) | X10: =IF(Q10=1,IF(SUBSTITUTE(SUBSTITUTE(SUBSTITUTE(SUBSTITUTE(SUBSTITUTE(SUBSTITUTE(SUBSTITUTE(SUBSTITUTE(SUBSTITUTE(SUBSTITUTE(SUBSTITUTE(SUBSTITUTE(LOWER(TRIM(A10)),"á","a"),"é","e"),"í","i"),"ó","o"),"ú","u"),"ü","u"),"ñ","n"),"à","a"),"è","e"),"ì","i"),"ò","o"),"ù","u")="","(sin apodo)",SUBSTITUTE(SUBSTITUTE(SUBSTITUTE(SUBSTITUTE(SUBSTITUTE(SUBSTITUTE(SUBSTITUTE(SUBSTITUTE(SUBSTITUTE(SUBSTITUTE(SUBSTITUTE(SUBSTITUTE(LOWER(TRIM(A10)),"á","a"),"é","e"),"í","i"),"ó","o"),"ú","u"),"ü","u"),"ñ","n"),"à","a"),"è","e"),"ì","i"),"ò","o"),"ù","u")),"") | Y10: =IF(X10="","",IF(IFERROR(COUNTIF(X$3:X10,"="&SUBSTITUTE(SUBSTITUTE(SUBSTITUTE(X10,"~","~~"),"*","~*"),"?","~?")),0)=1,1,"")) | Z10: =IF(T10=1,MAX(Z$2:Z9)+1,"")
A11: =IF(A$2=0,"",IFERROR(TRIM(INDEX('Pegar calibracion'!$A$1:$BZ$1001,10,A$2)&""),"")) | B11: =IF(B$2=0,"",IFERROR(TRIM(INDEX('Pegar calibracion'!$A$1:$BZ$1001,10,B$2)&""),"")) | C11: =IF(C$2=0,"",IFERROR(TRIM(INDEX('Pegar calibracion'!$A$1:$BZ$1001,10,C$2)&""),"")) | D11: =IF(D$2=0,"",IFERROR(TRIM(INDEX('Pegar calibracion'!$A$1:$BZ$1001,10,D$2)&""),"")) | E11: =IF(E$2=0,"",IFERROR(TRIM(INDEX('Pegar calibracion'!$A$1:$BZ$1001,10,E$2)&""),"")) | F11: =IF(F$2=0,"",IFERROR(TRIM(INDEX('Pegar calibracion'!$A$1:$BZ$1001,10,F$2)&""),"")) | G11: =IF(G$2=0,"",IFERROR(TRIM(INDEX('Pegar calibracion'!$A$1:$BZ$1001,10,G$2)&""),"")) | H11: =IF(H$2=0,"",IFERROR(TRIM(INDEX('Pegar calibracion'!$A$1:$BZ$1001,10,H$2)&""),"")) | ... L11: =IF(L$2=0,"",IFERROR(TRIM(INDEX('Pegar calibracion'!$A$1:$BZ$1001,10,L$2)&""),"")) | M11: =IF(D11="","",SUBSTITUTE(SUBSTITUTE(SUBSTITUTE(SUBSTITUTE(SUBSTITUTE(SUBSTITUTE(SUBSTITUTE(SUBSTITUTE(SUBSTITUTE(SUBSTITUTE(SUBSTITUTE(SUBSTITUTE(LOWER(TRIM(D11)),"á","a"),"é","e"),"í","i"),"ó","o"),"ú","u"),"ü","u"),"ñ","n"),"à","a"),"è","e"),"ì","i"),"ò","o"),"ù","u")) | N11: =IF(F11="","",SUBSTITUTE(SUBSTITUTE(SUBSTITUTE(SUBSTITUTE(SUBSTITUTE(SUBSTITUTE(SUBSTITUTE(SUBSTITUTE(SUBSTITUTE(SUBSTITUTE(SUBSTITUTE(SUBSTITUTE(LOWER(TRIM(F11)),"á","a"),"é","e"),"í","i"),"ó","o"),"ú","u"),"ü","u"),"ñ","n"),"à","a"),"è","e"),"ì","i"),"ò","o"),"ù","u")) | O11: =IF(M11="confiable",2,IF(M11="dudosa",1,IF(M11="no confiable",0,""))) | P11: =IF(N11="confiable",2,IF(N11="dudosa",1,IF(N11="no confiable",0,""))) | Q11: =IF(AND(ISNUMBER(O11),ISNUMBER(P11)),1,"") | R11: =IF(Q11=1,IF(O11=P11,"Sí","No"),"") | S11: =IF(Q11=1,IF(P11<O11,"Más estricto",IF(P11>O11,"Más permisivo","Igual")),"") | T11: =IF(Q11=1,IF(ABS(O11-P11)=2,1,0),"") | U11: =IF(H11="","","|"&SUBSTITUTE(SUBSTITUTE(TRIM(H11)," |","|"),"| ","|")&"|") | V11: =IF(AND(Q11=1,B11<>""),IF(IFERROR(COUNTIFS(B$3:B11,"="&SUBSTITUTE(SUBSTITUTE(SUBSTITUTE(B11,"~","~~"),"*","~*"),"?","~?"),Q$3:Q11,1),0)=1,MAX(V$2:V10)+1,""),"") | W11: =IF(V11="","",COUNTIFS($B$3:$B$1002,"="&SUBSTITUTE(SUBSTITUTE(SUBSTITUTE(B11,"~","~~"),"*","~*"),"?","~?"),$Q$3:$Q$1002,1)*10000-V11) | X11: =IF(Q11=1,IF(SUBSTITUTE(SUBSTITUTE(SUBSTITUTE(SUBSTITUTE(SUBSTITUTE(SUBSTITUTE(SUBSTITUTE(SUBSTITUTE(SUBSTITUTE(SUBSTITUTE(SUBSTITUTE(SUBSTITUTE(LOWER(TRIM(A11)),"á","a"),"é","e"),"í","i"),"ó","o"),"ú","u"),"ü","u"),"ñ","n"),"à","a"),"è","e"),"ì","i"),"ò","o"),"ù","u")="","(sin apodo)",SUBSTITUTE(SUBSTITUTE(SUBSTITUTE(SUBSTITUTE(SUBSTITUTE(SUBSTITUTE(SUBSTITUTE(SUBSTITUTE(SUBSTITUTE(SUBSTITUTE(SUBSTITUTE(SUBSTITUTE(LOWER(TRIM(A11)),"á","a"),"é","e"),"í","i"),"ó","o"),"ú","u"),"ü","u"),"ñ","n"),"à","a"),"è","e"),"ì","i"),"ò","o"),"ù","u")),"") | Y11: =IF(X11="","",IF(IFERROR(COUNTIF(X$3:X11,"="&SUBSTITUTE(SUBSTITUTE(SUBSTITUTE(X11,"~","~~"),"*","~*"),"?","~?")),0)=1,1,"")) | Z11: =IF(T11=1,MAX(Z$2:Z10)+1,"")
A12: =IF(A$2=0,"",IFERROR(TRIM(INDEX('Pegar calibracion'!$A$1:$BZ$1001,11,A$2)&""),"")) | B12: =IF(B$2=0,"",IFERROR(TRIM(INDEX('Pegar calibracion'!$A$1:$BZ$1001,11,B$2)&""),"")) | C12: =IF(C$2=0,"",IFERROR(TRIM(INDEX('Pegar calibracion'!$A$1:$BZ$1001,11,C$2)&""),"")) | D12: =IF(D$2=0,"",IFERROR(TRIM(INDEX('Pegar calibracion'!$A$1:$BZ$1001,11,D$2)&""),"")) | E12: =IF(E$2=0,"",IFERROR(TRIM(INDEX('Pegar calibracion'!$A$1:$BZ$1001,11,E$2)&""),"")) | F12: =IF(F$2=0,"",IFERROR(TRIM(INDEX('Pegar calibracion'!$A$1:$BZ$1001,11,F$2)&""),"")) | G12: =IF(G$2=0,"",IFERROR(TRIM(INDEX('Pegar calibracion'!$A$1:$BZ$1001,11,G$2)&""),"")) | H12: =IF(H$2=0,"",IFERROR(TRIM(INDEX('Pegar calibracion'!$A$1:$BZ$1001,11,H$2)&""),"")) | ... L12: =IF(L$2=0,"",IFERROR(TRIM(INDEX('Pegar calibracion'!$A$1:$BZ$1001,11,L$2)&""),"")) | M12: =IF(D12="","",SUBSTITUTE(SUBSTITUTE(SUBSTITUTE(SUBSTITUTE(SUBSTITUTE(SUBSTITUTE(SUBSTITUTE(SUBSTITUTE(SUBSTITUTE(SUBSTITUTE(SUBSTITUTE(SUBSTITUTE(LOWER(TRIM(D12)),"á","a"),"é","e"),"í","i"),"ó","o"),"ú","u"),"ü","u"),"ñ","n"),"à","a"),"è","e"),"ì","i"),"ò","o"),"ù","u")) | N12: =IF(F12="","",SUBSTITUTE(SUBSTITUTE(SUBSTITUTE(SUBSTITUTE(SUBSTITUTE(SUBSTITUTE(SUBSTITUTE(SUBSTITUTE(SUBSTITUTE(SUBSTITUTE(SUBSTITUTE(SUBSTITUTE(LOWER(TRIM(F12)),"á","a"),"é","e"),"í","i"),"ó","o"),"ú","u"),"ü","u"),"ñ","n"),"à","a"),"è","e"),"ì","i"),"ò","o"),"ù","u")) | O12: =IF(M12="confiable",2,IF(M12="dudosa",1,IF(M12="no confiable",0,""))) | P12: =IF(N12="confiable",2,IF(N12="dudosa",1,IF(N12="no confiable",0,""))) | Q12: =IF(AND(ISNUMBER(O12),ISNUMBER(P12)),1,"") | R12: =IF(Q12=1,IF(O12=P12,"Sí","No"),"") | S12: =IF(Q12=1,IF(P12<O12,"Más estricto",IF(P12>O12,"Más permisivo","Igual")),"") | T12: =IF(Q12=1,IF(ABS(O12-P12)=2,1,0),"") | U12: =IF(H12="","","|"&SUBSTITUTE(SUBSTITUTE(TRIM(H12)," |","|"),"| ","|")&"|") | V12: =IF(AND(Q12=1,B12<>""),IF(IFERROR(COUNTIFS(B$3:B12,"="&SUBSTITUTE(SUBSTITUTE(SUBSTITUTE(B12,"~","~~"),"*","~*"),"?","~?"),Q$3:Q12,1),0)=1,MAX(V$2:V11)+1,""),"") | W12: =IF(V12="","",COUNTIFS($B$3:$B$1002,"="&SUBSTITUTE(SUBSTITUTE(SUBSTITUTE(B12,"~","~~"),"*","~*"),"?","~?"),$Q$3:$Q$1002,1)*10000-V12) | X12: =IF(Q12=1,IF(SUBSTITUTE(SUBSTITUTE(SUBSTITUTE(SUBSTITUTE(SUBSTITUTE(SUBSTITUTE(SUBSTITUTE(SUBSTITUTE(SUBSTITUTE(SUBSTITUTE(SUBSTITUTE(SUBSTITUTE(LOWER(TRIM(A12)),"á","a"),"é","e"),"í","i"),"ó","o"),"ú","u"),"ü","u"),"ñ","n"),"à","a"),"è","e"),"ì","i"),"ò","o"),"ù","u")="","(sin apodo)",SUBSTITUTE(SUBSTITUTE(SUBSTITUTE(SUBSTITUTE(SUBSTITUTE(SUBSTITUTE(SUBSTITUTE(SUBSTITUTE(SUBSTITUTE(SUBSTITUTE(SUBSTITUTE(SUBSTITUTE(LOWER(TRIM(A12)),"á","a"),"é","e"),"í","i"),"ó","o"),"ú","u"),"ü","u"),"ñ","n"),"à","a"),"è","e"),"ì","i"),"ò","o"),"ù","u")),"") | Y12: =IF(X12="","",IF(IFERROR(COUNTIF(X$3:X12,"="&SUBSTITUTE(SUBSTITUTE(SUBSTITUTE(X12,"~","~~"),"*","~*"),"?","~?")),0)=1,1,"")) | Z12: =IF(T12=1,MAX(Z$2:Z11)+1,"")
A13: =IF(A$2=0,"",IFERROR(TRIM(INDEX('Pegar calibracion'!$A$1:$BZ$1001,12,A$2)&""),"")) | B13: =IF(B$2=0,"",IFERROR(TRIM(INDEX('Pegar calibracion'!$A$1:$BZ$1001,12,B$2)&""),"")) | C13: =IF(C$2=0,"",IFERROR(TRIM(INDEX('Pegar calibracion'!$A$1:$BZ$1001,12,C$2)&""),"")) | D13: =IF(D$2=0,"",IFERROR(TRIM(INDEX('Pegar calibracion'!$A$1:$BZ$1001,12,D$2)&""),"")) | E13: =IF(E$2=0,"",IFERROR(TRIM(INDEX('Pegar calibracion'!$A$1:$BZ$1001,12,E$2)&""),"")) | F13: =IF(F$2=0,"",IFERROR(TRIM(INDEX('Pegar calibracion'!$A$1:$BZ$1001,12,F$2)&""),"")) | G13: =IF(G$2=0,"",IFERROR(TRIM(INDEX('Pegar calibracion'!$A$1:$BZ$1001,12,G$2)&""),"")) | H13: =IF(H$2=0,"",IFERROR(TRIM(INDEX('Pegar calibracion'!$A$1:$BZ$1001,12,H$2)&""),"")) | ... L13: =IF(L$2=0,"",IFERROR(TRIM(INDEX('Pegar calibracion'!$A$1:$BZ$1001,12,L$2)&""),"")) | M13: =IF(D13="","",SUBSTITUTE(SUBSTITUTE(SUBSTITUTE(SUBSTITUTE(SUBSTITUTE(SUBSTITUTE(SUBSTITUTE(SUBSTITUTE(SUBSTITUTE(SUBSTITUTE(SUBSTITUTE(SUBSTITUTE(LOWER(TRIM(D13)),"á","a"),"é","e"),"í","i"),"ó","o"),"ú","u"),"ü","u"),"ñ","n"),"à","a"),"è","e"),"ì","i"),"ò","o"),"ù","u")) | N13: =IF(F13="","",SUBSTITUTE(SUBSTITUTE(SUBSTITUTE(SUBSTITUTE(SUBSTITUTE(SUBSTITUTE(SUBSTITUTE(SUBSTITUTE(SUBSTITUTE(SUBSTITUTE(SUBSTITUTE(SUBSTITUTE(LOWER(TRIM(F13)),"á","a"),"é","e"),"í","i"),"ó","o"),"ú","u"),"ü","u"),"ñ","n"),"à","a"),"è","e"),"ì","i"),"ò","o"),"ù","u")) | O13: =IF(M13="confiable",2,IF(M13="dudosa",1,IF(M13="no confiable",0,""))) | P13: =IF(N13="confiable",2,IF(N13="dudosa",1,IF(N13="no confiable",0,""))) | Q13: =IF(AND(ISNUMBER(O13),ISNUMBER(P13)),1,"") | R13: =IF(Q13=1,IF(O13=P13,"Sí","No"),"") | S13: =IF(Q13=1,IF(P13<O13,"Más estricto",IF(P13>O13,"Más permisivo","Igual")),"") | T13: =IF(Q13=1,IF(ABS(O13-P13)=2,1,0),"") | U13: =IF(H13="","","|"&SUBSTITUTE(SUBSTITUTE(TRIM(H13)," |","|"),"| ","|")&"|") | V13: =IF(AND(Q13=1,B13<>""),IF(IFERROR(COUNTIFS(B$3:B13,"="&SUBSTITUTE(SUBSTITUTE(SUBSTITUTE(B13,"~","~~"),"*","~*"),"?","~?"),Q$3:Q13,1),0)=1,MAX(V$2:V12)+1,""),"") | W13: =IF(V13="","",COUNTIFS($B$3:$B$1002,"="&SUBSTITUTE(SUBSTITUTE(SUBSTITUTE(B13,"~","~~"),"*","~*"),"?","~?"),$Q$3:$Q$1002,1)*10000-V13) | X13: =IF(Q13=1,IF(SUBSTITUTE(SUBSTITUTE(SUBSTITUTE(SUBSTITUTE(SUBSTITUTE(SUBSTITUTE(SUBSTITUTE(SUBSTITUTE(SUBSTITUTE(SUBSTITUTE(SUBSTITUTE(SUBSTITUTE(LOWER(TRIM(A13)),"á","a"),"é","e"),"í","i"),"ó","o"),"ú","u"),"ü","u"),"ñ","n"),"à","a"),"è","e"),"ì","i"),"ò","o"),"ù","u")="","(sin apodo)",SUBSTITUTE(SUBSTITUTE(SUBSTITUTE(SUBSTITUTE(SUBSTITUTE(SUBSTITUTE(SUBSTITUTE(SUBSTITUTE(SUBSTITUTE(SUBSTITUTE(SUBSTITUTE(SUBSTITUTE(LOWER(TRIM(A13)),"á","a"),"é","e"),"í","i"),"ó","o"),"ú","u"),"ü","u"),"ñ","n"),"à","a"),"è","e"),"ì","i"),"ò","o"),"ù","u")),"") | Y13: =IF(X13="","",IF(IFERROR(COUNTIF(X$3:X13,"="&SUBSTITUTE(SUBSTITUTE(SUBSTITUTE(X13,"~","~~"),"*","~*"),"?","~?")),0)=1,1,"")) | Z13: =IF(T13=1,MAX(Z$2:Z12)+1,"")
A14: =IF(A$2=0,"",IFERROR(TRIM(INDEX('Pegar calibracion'!$A$1:$BZ$1001,13,A$2)&""),"")) | B14: =IF(B$2=0,"",IFERROR(TRIM(INDEX('Pegar calibracion'!$A$1:$BZ$1001,13,B$2)&""),"")) | C14: =IF(C$2=0,"",IFERROR(TRIM(INDEX('Pegar calibracion'!$A$1:$BZ$1001,13,C$2)&""),"")) | D14: =IF(D$2=0,"",IFERROR(TRIM(INDEX('Pegar calibracion'!$A$1:$BZ$1001,13,D$2)&""),"")) | E14: =IF(E$2=0,"",IFERROR(TRIM(INDEX('Pegar calibracion'!$A$1:$BZ$1001,13,E$2)&""),"")) | F14: =IF(F$2=0,"",IFERROR(TRIM(INDEX('Pegar calibracion'!$A$1:$BZ$1001,13,F$2)&""),"")) | G14: =IF(G$2=0,"",IFERROR(TRIM(INDEX('Pegar calibracion'!$A$1:$BZ$1001,13,G$2)&""),"")) | H14: =IF(H$2=0,"",IFERROR(TRIM(INDEX('Pegar calibracion'!$A$1:$BZ$1001,13,H$2)&""),"")) | ... L14: =IF(L$2=0,"",IFERROR(TRIM(INDEX('Pegar calibracion'!$A$1:$BZ$1001,13,L$2)&""),"")) | M14: =IF(D14="","",SUBSTITUTE(SUBSTITUTE(SUBSTITUTE(SUBSTITUTE(SUBSTITUTE(SUBSTITUTE(SUBSTITUTE(SUBSTITUTE(SUBSTITUTE(SUBSTITUTE(SUBSTITUTE(SUBSTITUTE(LOWER(TRIM(D14)),"á","a"),"é","e"),"í","i"),"ó","o"),"ú","u"),"ü","u"),"ñ","n"),"à","a"),"è","e"),"ì","i"),"ò","o"),"ù","u")) | N14: =IF(F14="","",SUBSTITUTE(SUBSTITUTE(SUBSTITUTE(SUBSTITUTE(SUBSTITUTE(SUBSTITUTE(SUBSTITUTE(SUBSTITUTE(SUBSTITUTE(SUBSTITUTE(SUBSTITUTE(SUBSTITUTE(LOWER(TRIM(F14)),"á","a"),"é","e"),"í","i"),"ó","o"),"ú","u"),"ü","u"),"ñ","n"),"à","a"),"è","e"),"ì","i"),"ò","o"),"ù","u")) | O14: =IF(M14="confiable",2,IF(M14="dudosa",1,IF(M14="no confiable",0,""))) | P14: =IF(N14="confiable",2,IF(N14="dudosa",1,IF(N14="no confiable",0,""))) | Q14: =IF(AND(ISNUMBER(O14),ISNUMBER(P14)),1,"") | R14: =IF(Q14=1,IF(O14=P14,"Sí","No"),"") | S14: =IF(Q14=1,IF(P14<O14,"Más estricto",IF(P14>O14,"Más permisivo","Igual")),"") | T14: =IF(Q14=1,IF(ABS(O14-P14)=2,1,0),"") | U14: =IF(H14="","","|"&SUBSTITUTE(SUBSTITUTE(TRIM(H14)," |","|"),"| ","|")&"|") | V14: =IF(AND(Q14=1,B14<>""),IF(IFERROR(COUNTIFS(B$3:B14,"="&SUBSTITUTE(SUBSTITUTE(SUBSTITUTE(B14,"~","~~"),"*","~*"),"?","~?"),Q$3:Q14,1),0)=1,MAX(V$2:V13)+1,""),"") | W14: =IF(V14="","",COUNTIFS($B$3:$B$1002,"="&SUBSTITUTE(SUBSTITUTE(SUBSTITUTE(B14,"~","~~"),"*","~*"),"?","~?"),$Q$3:$Q$1002,1)*10000-V14) | X14: =IF(Q14=1,IF(SUBSTITUTE(SUBSTITUTE(SUBSTITUTE(SUBSTITUTE(SUBSTITUTE(SUBSTITUTE(SUBSTITUTE(SUBSTITUTE(SUBSTITUTE(SUBSTITUTE(SUBSTITUTE(SUBSTITUTE(LOWER(TRIM(A14)),"á","a"),"é","e"),"í","i"),"ó","o"),"ú","u"),"ü","u"),"ñ","n"),"à","a"),"è","e"),"ì","i"),"ò","o"),"ù","u")="","(sin apodo)",SUBSTITUTE(SUBSTITUTE(SUBSTITUTE(SUBSTITUTE(SUBSTITUTE(SUBSTITUTE(SUBSTITUTE(SUBSTITUTE(SUBSTITUTE(SUBSTITUTE(SUBSTITUTE(SUBSTITUTE(LOWER(TRIM(A14)),"á","a"),"é","e"),"í","i"),"ó","o"),"ú","u"),"ü","u"),"ñ","n"),"à","a"),"è","e"),"ì","i"),"ò","o"),"ù","u")),"") | Y14: =IF(X14="","",IF(IFERROR(COUNTIF(X$3:X14,"="&SUBSTITUTE(SUBSTITUTE(SUBSTITUTE(X14,"~","~~"),"*","~*"),"?","~?")),0)=1,1,"")) | Z14: =IF(T14=1,MAX(Z$2:Z13)+1,"")
A15: =IF(A$2=0,"",IFERROR(TRIM(INDEX('Pegar calibracion'!$A$1:$BZ$1001,14,A$2)&""),"")) | B15: =IF(B$2=0,"",IFERROR(TRIM(INDEX('Pegar calibracion'!$A$1:$BZ$1001,14,B$2)&""),"")) | C15: =IF(C$2=0,"",IFERROR(TRIM(INDEX('Pegar calibracion'!$A$1:$BZ$1001,14,C$2)&""),"")) | D15: =IF(D$2=0,"",IFERROR(TRIM(INDEX('Pegar calibracion'!$A$1:$BZ$1001,14,D$2)&""),"")) | E15: =IF(E$2=0,"",IFERROR(TRIM(INDEX('Pegar calibracion'!$A$1:$BZ$1001,14,E$2)&""),"")) | F15: =IF(F$2=0,"",IFERROR(TRIM(INDEX('Pegar calibracion'!$A$1:$BZ$1001,14,F$2)&""),"")) | G15: =IF(G$2=0,"",IFERROR(TRIM(INDEX('Pegar calibracion'!$A$1:$BZ$1001,14,G$2)&""),"")) | H15: =IF(H$2=0,"",IFERROR(TRIM(INDEX('Pegar calibracion'!$A$1:$BZ$1001,14,H$2)&""),"")) | ... L15: =IF(L$2=0,"",IFERROR(TRIM(INDEX('Pegar calibracion'!$A$1:$BZ$1001,14,L$2)&""),"")) | M15: =IF(D15="","",SUBSTITUTE(SUBSTITUTE(SUBSTITUTE(SUBSTITUTE(SUBSTITUTE(SUBSTITUTE(SUBSTITUTE(SUBSTITUTE(SUBSTITUTE(SUBSTITUTE(SUBSTITUTE(SUBSTITUTE(LOWER(TRIM(D15)),"á","a"),"é","e"),"í","i"),"ó","o"),"ú","u"),"ü","u"),"ñ","n"),"à","a"),"è","e"),"ì","i"),"ò","o"),"ù","u")) | N15: =IF(F15="","",SUBSTITUTE(SUBSTITUTE(SUBSTITUTE(SUBSTITUTE(SUBSTITUTE(SUBSTITUTE(SUBSTITUTE(SUBSTITUTE(SUBSTITUTE(SUBSTITUTE(SUBSTITUTE(SUBSTITUTE(LOWER(TRIM(F15)),"á","a"),"é","e"),"í","i"),"ó","o"),"ú","u"),"ü","u"),"ñ","n"),"à","a"),"è","e"),"ì","i"),"ò","o"),"ù","u")) | O15: =IF(M15="confiable",2,IF(M15="dudosa",1,IF(M15="no confiable",0,""))) | P15: =IF(N15="confiable",2,IF(N15="dudosa",1,IF(N15="no confiable",0,""))) | Q15: =IF(AND(ISNUMBER(O15),ISNUMBER(P15)),1,"") | R15: =IF(Q15=1,IF(O15=P15,"Sí","No"),"") | S15: =IF(Q15=1,IF(P15<O15,"Más estricto",IF(P15>O15,"Más permisivo","Igual")),"") | T15: =IF(Q15=1,IF(ABS(O15-P15)=2,1,0),"") | U15: =IF(H15="","","|"&SUBSTITUTE(SUBSTITUTE(TRIM(H15)," |","|"),"| ","|")&"|") | V15: =IF(AND(Q15=1,B15<>""),IF(IFERROR(COUNTIFS(B$3:B15,"="&SUBSTITUTE(SUBSTITUTE(SUBSTITUTE(B15,"~","~~"),"*","~*"),"?","~?"),Q$3:Q15,1),0)=1,MAX(V$2:V14)+1,""),"") | W15: =IF(V15="","",COUNTIFS($B$3:$B$1002,"="&SUBSTITUTE(SUBSTITUTE(SUBSTITUTE(B15,"~","~~"),"*","~*"),"?","~?"),$Q$3:$Q$1002,1)*10000-V15) | X15: =IF(Q15=1,IF(SUBSTITUTE(SUBSTITUTE(SUBSTITUTE(SUBSTITUTE(SUBSTITUTE(SUBSTITUTE(SUBSTITUTE(SUBSTITUTE(SUBSTITUTE(SUBSTITUTE(SUBSTITUTE(SUBSTITUTE(LOWER(TRIM(A15)),"á","a"),"é","e"),"í","i"),"ó","o"),"ú","u"),"ü","u"),"ñ","n"),"à","a"),"è","e"),"ì","i"),"ò","o"),"ù","u")="","(sin apodo)",SUBSTITUTE(SUBSTITUTE(SUBSTITUTE(SUBSTITUTE(SUBSTITUTE(SUBSTITUTE(SUBSTITUTE(SUBSTITUTE(SUBSTITUTE(SUBSTITUTE(SUBSTITUTE(SUBSTITUTE(LOWER(TRIM(A15)),"á","a"),"é","e"),"í","i"),"ó","o"),"ú","u"),"ü","u"),"ñ","n"),"à","a"),"è","e"),"ì","i"),"ò","o"),"ù","u")),"") | Y15: =IF(X15="","",IF(IFERROR(COUNTIF(X$3:X15,"="&SUBSTITUTE(SUBSTITUTE(SUBSTITUTE(X15,"~","~~"),"*","~*"),"?","~?")),0)=1,1,"")) | Z15: =IF(T15=1,MAX(Z$2:Z14)+1,"")
A16: =IF(A$2=0,"",IFERROR(TRIM(INDEX('Pegar calibracion'!$A$1:$BZ$1001,15,A$2)&""),"")) | B16: =IF(B$2=0,"",IFERROR(TRIM(INDEX('Pegar calibracion'!$A$1:$BZ$1001,15,B$2)&""),"")) | C16: =IF(C$2=0,"",IFERROR(TRIM(INDEX('Pegar calibracion'!$A$1:$BZ$1001,15,C$2)&""),"")) | D16: =IF(D$2=0,"",IFERROR(TRIM(INDEX('Pegar calibracion'!$A$1:$BZ$1001,15,D$2)&""),"")) | E16: =IF(E$2=0,"",IFERROR(TRIM(INDEX('Pegar calibracion'!$A$1:$BZ$1001,15,E$2)&""),"")) | F16: =IF(F$2=0,"",IFERROR(TRIM(INDEX('Pegar calibracion'!$A$1:$BZ$1001,15,F$2)&""),"")) | G16: =IF(G$2=0,"",IFERROR(TRIM(INDEX('Pegar calibracion'!$A$1:$BZ$1001,15,G$2)&""),"")) | H16: =IF(H$2=0,"",IFERROR(TRIM(INDEX('Pegar calibracion'!$A$1:$BZ$1001,15,H$2)&""),"")) | ... L16: =IF(L$2=0,"",IFERROR(TRIM(INDEX('Pegar calibracion'!$A$1:$BZ$1001,15,L$2)&""),"")) | M16: =IF(D16="","",SUBSTITUTE(SUBSTITUTE(SUBSTITUTE(SUBSTITUTE(SUBSTITUTE(SUBSTITUTE(SUBSTITUTE(SUBSTITUTE(SUBSTITUTE(SUBSTITUTE(SUBSTITUTE(SUBSTITUTE(LOWER(TRIM(D16)),"á","a"),"é","e"),"í","i"),"ó","o"),"ú","u"),"ü","u"),"ñ","n"),"à","a"),"è","e"),"ì","i"),"ò","o"),"ù","u")) | N16: =IF(F16="","",SUBSTITUTE(SUBSTITUTE(SUBSTITUTE(SUBSTITUTE(SUBSTITUTE(SUBSTITUTE(SUBSTITUTE(SUBSTITUTE(SUBSTITUTE(SUBSTITUTE(SUBSTITUTE(SUBSTITUTE(LOWER(TRIM(F16)),"á","a"),"é","e"),"í","i"),"ó","o"),"ú","u"),"ü","u"),"ñ","n"),"à","a"),"è","e"),"ì","i"),"ò","o"),"ù","u")) | O16: =IF(M16="confiable",2,IF(M16="dudosa",1,IF(M16="no confiable",0,""))) | P16: =IF(N16="confiable",2,IF(N16="dudosa",1,IF(N16="no confiable",0,""))) | Q16: =IF(AND(ISNUMBER(O16),ISNUMBER(P16)),1,"") | R16: =IF(Q16=1,IF(O16=P16,"Sí","No"),"") | S16: =IF(Q16=1,IF(P16<O16,"Más estricto",IF(P16>O16,"Más permisivo","Igual")),"") | T16: =IF(Q16=1,IF(ABS(O16-P16)=2,1,0),"") | U16: =IF(H16="","","|"&SUBSTITUTE(SUBSTITUTE(TRIM(H16)," |","|"),"| ","|")&"|") | V16: =IF(AND(Q16=1,B16<>""),IF(IFERROR(COUNTIFS(B$3:B16,"="&SUBSTITUTE(SUBSTITUTE(SUBSTITUTE(B16,"~","~~"),"*","~*"),"?","~?"),Q$3:Q16,1),0)=1,MAX(V$2:V15)+1,""),"") | W16: =IF(V16="","",COUNTIFS($B$3:$B$1002,"="&SUBSTITUTE(SUBSTITUTE(SUBSTITUTE(B16,"~","~~"),"*","~*"),"?","~?"),$Q$3:$Q$1002,1)*10000-V16) | X16: =IF(Q16=1,IF(SUBSTITUTE(SUBSTITUTE(SUBSTITUTE(SUBSTITUTE(SUBSTITUTE(SUBSTITUTE(SUBSTITUTE(SUBSTITUTE(SUBSTITUTE(SUBSTITUTE(SUBSTITUTE(SUBSTITUTE(LOWER(TRIM(A16)),"á","a"),"é","e"),"í","i"),"ó","o"),"ú","u"),"ü","u"),"ñ","n"),"à","a"),"è","e"),"ì","i"),"ò","o"),"ù","u")="","(sin apodo)",SUBSTITUTE(SUBSTITUTE(SUBSTITUTE(SUBSTITUTE(SUBSTITUTE(SUBSTITUTE(SUBSTITUTE(SUBSTITUTE(SUBSTITUTE(SUBSTITUTE(SUBSTITUTE(SUBSTITUTE(LOWER(TRIM(A16)),"á","a"),"é","e"),"í","i"),"ó","o"),"ú","u"),"ü","u"),"ñ","n"),"à","a"),"è","e"),"ì","i"),"ò","o"),"ù","u")),"") | Y16: =IF(X16="","",IF(IFERROR(COUNTIF(X$3:X16,"="&SUBSTITUTE(SUBSTITUTE(SUBSTITUTE(X16,"~","~~"),"*","~*"),"?","~?")),0)=1,1,"")) | Z16: =IF(T16=1,MAX(Z$2:Z15)+1,"")
A17: =IF(A$2=0,"",IFERROR(TRIM(INDEX('Pegar calibracion'!$A$1:$BZ$1001,16,A$2)&""),"")) | B17: =IF(B$2=0,"",IFERROR(TRIM(INDEX('Pegar calibracion'!$A$1:$BZ$1001,16,B$2)&""),"")) | C17: =IF(C$2=0,"",IFERROR(TRIM(INDEX('Pegar calibracion'!$A$1:$BZ$1001,16,C$2)&""),"")) | D17: =IF(D$2=0,"",IFERROR(TRIM(INDEX('Pegar calibracion'!$A$1:$BZ$1001,16,D$2)&""),"")) | E17: =IF(E$2=0,"",IFERROR(TRIM(INDEX('Pegar calibracion'!$A$1:$BZ$1001,16,E$2)&""),"")) | F17: =IF(F$2=0,"",IFERROR(TRIM(INDEX('Pegar calibracion'!$A$1:$BZ$1001,16,F$2)&""),"")) | G17: =IF(G$2=0,"",IFERROR(TRIM(INDEX('Pegar calibracion'!$A$1:$BZ$1001,16,G$2)&""),"")) | H17: =IF(H$2=0,"",IFERROR(TRIM(INDEX('Pegar calibracion'!$A$1:$BZ$1001,16,H$2)&""),"")) | ... L17: =IF(L$2=0,"",IFERROR(TRIM(INDEX('Pegar calibracion'!$A$1:$BZ$1001,16,L$2)&""),"")) | M17: =IF(D17="","",SUBSTITUTE(SUBSTITUTE(SUBSTITUTE(SUBSTITUTE(SUBSTITUTE(SUBSTITUTE(SUBSTITUTE(SUBSTITUTE(SUBSTITUTE(SUBSTITUTE(SUBSTITUTE(SUBSTITUTE(LOWER(TRIM(D17)),"á","a"),"é","e"),"í","i"),"ó","o"),"ú","u"),"ü","u"),"ñ","n"),"à","a"),"è","e"),"ì","i"),"ò","o"),"ù","u")) | N17: =IF(F17="","",SUBSTITUTE(SUBSTITUTE(SUBSTITUTE(SUBSTITUTE(SUBSTITUTE(SUBSTITUTE(SUBSTITUTE(SUBSTITUTE(SUBSTITUTE(SUBSTITUTE(SUBSTITUTE(SUBSTITUTE(LOWER(TRIM(F17)),"á","a"),"é","e"),"í","i"),"ó","o"),"ú","u"),"ü","u"),"ñ","n"),"à","a"),"è","e"),"ì","i"),"ò","o"),"ù","u")) | O17: =IF(M17="confiable",2,IF(M17="dudosa",1,IF(M17="no confiable",0,""))) | P17: =IF(N17="confiable",2,IF(N17="dudosa",1,IF(N17="no confiable",0,""))) | Q17: =IF(AND(ISNUMBER(O17),ISNUMBER(P17)),1,"") | R17: =IF(Q17=1,IF(O17=P17,"Sí","No"),"") | S17: =IF(Q17=1,IF(P17<O17,"Más estricto",IF(P17>O17,"Más permisivo","Igual")),"") | T17: =IF(Q17=1,IF(ABS(O17-P17)=2,1,0),"") | U17: =IF(H17="","","|"&SUBSTITUTE(SUBSTITUTE(TRIM(H17)," |","|"),"| ","|")&"|") | V17: =IF(AND(Q17=1,B17<>""),IF(IFERROR(COUNTIFS(B$3:B17,"="&SUBSTITUTE(SUBSTITUTE(SUBSTITUTE(B17,"~","~~"),"*","~*"),"?","~?"),Q$3:Q17,1),0)=1,MAX(V$2:V16)+1,""),"") | W17: =IF(V17="","",COUNTIFS($B$3:$B$1002,"="&SUBSTITUTE(SUBSTITUTE(SUBSTITUTE(B17,"~","~~"),"*","~*"),"?","~?"),$Q$3:$Q$1002,1)*10000-V17) | X17: =IF(Q17=1,IF(SUBSTITUTE(SUBSTITUTE(SUBSTITUTE(SUBSTITUTE(SUBSTITUTE(SUBSTITUTE(SUBSTITUTE(SUBSTITUTE(SUBSTITUTE(SUBSTITUTE(SUBSTITUTE(SUBSTITUTE(LOWER(TRIM(A17)),"á","a"),"é","e"),"í","i"),"ó","o"),"ú","u"),"ü","u"),"ñ","n"),"à","a"),"è","e"),"ì","i"),"ò","o"),"ù","u")="","(sin apodo)",SUBSTITUTE(SUBSTITUTE(SUBSTITUTE(SUBSTITUTE(SUBSTITUTE(SUBSTITUTE(SUBSTITUTE(SUBSTITUTE(SUBSTITUTE(SUBSTITUTE(SUBSTITUTE(SUBSTITUTE(LOWER(TRIM(A17)),"á","a"),"é","e"),"í","i"),"ó","o"),"ú","u"),"ü","u"),"ñ","n"),"à","a"),"è","e"),"ì","i"),"ò","o"),"ù","u")),"") | Y17: =IF(X17="","",IF(IFERROR(COUNTIF(X$3:X17,"="&SUBSTITUTE(SUBSTITUTE(SUBSTITUTE(X17,"~","~~"),"*","~*"),"?","~?")),0)=1,1,"")) | Z17: =IF(T17=1,MAX(Z$2:Z16)+1,"")
